Workbook

Sheet API
A1: can_transact | B1: can_select | C1: chance_of_playing_next_round | D1: chance_of_playing_this_round | E1: code | F1: cost_change_event | G1: cost_change_event_fall | H1: cost_change_start | I1: cost_change_start_fall | J1: price_change_percent | K1: dreamteam_count | L1: element_type | M1: ep_next | N1: ep_this | O1: event_points | P1: first_name | Q1: form | R1: id | S1: in_dreamteam | T1: news | U1: news_added | V1: now_cost | W1: photo | X1: points_per_game | Y1: removed | Z1: second_name | AA1: selected_by_percent | AB1: special | AC1: squad_number | AD1: status | AE1: team | AF1: team_code | AG1: total_points | AH1: transfers_in | AI1: transfers_in_event | AJ1: transfers_out | AK1: transfers_out_event | AL1: value_form | AM1: value_season | AN1: web_name | AO1: known_name | AP1: region | AQ1: team_join_date | AR1: birth_date | AS1: has_temporary_code | AT1: opta_code | AU1: minutes | AV1: goals_scored | AW1: assists | AX1: clean_sheets | AY1: goals_conceded | AZ1: own_goals | BA1: penalties_saved | BB1: penalties_missed | BC1: yellow_cards | BD1: red_cards | BE1: saves | BF1: bonus | BG1: bps | BH1: influence | BI1: creativity | BJ1: threat | BK1: ict_index | BL1: clearances_blocks_interceptions | BM1: recoveries | BN1: tackles | BO1: defensive_contribution | BP1: starts | BQ1: expected_goals | BR1: expected_assists | BS1: expected_goal_involvements | BT1: expected_goals_conceded | BU1: corners_and_indirect_freekicks_order | BV1: corners_and_indirect_freekicks_text | BW1: direct_freekicks_order | BX1: direct_freekicks_text | BY1: penalties_order | BZ1: penalties_text | CA1: scout_risks | CB1: scout_news_link | CC1: influence_rank | CD1: influence_rank_type | CE1: creativity_rank | CF1: creativity_rank_type | CG1: threat_rank | CH1: threat_rank_type | CI1: ict_index_rank | CJ1: ict_index_rank_type | CK1: expected_goals_per_90 | CL1: saves_per_90 | CM1: expected_assists_per_90 | CN1: expected_goal_involvements_per_90 | CO1: expected_goals_conceded_per_90 | CP1: goals_conceded_per_90 | CQ1: now_cost_rank | CR1: now_cost_rank_type | CS1: form_rank | CT1: form_rank_type | CU1: points_per_game_rank | CV1: points_per_game_rank_type | CW1: selected_rank | CX1: selected_rank_type | CY1: starts_per_90 | CZ1: clean_sheets_per_90 | DA1: defensive_contribution_per_90
A2: TRUE | B2: TRUE | E2: 154561 | F2: 0 | G2: 0 | H2: 0 | I2: 0 | J2: 0 | K2: 0 | L2: 1 | M2: 4 | O2: 0 | P2: David | Q2: 0 | R2: 1 | S2: FALSE | V2: 60 | W2: 154561.jpg | X2: 4.4 | Y2: FALSE | Z2: Raya Martín | AA2: 29.3 | AB2: FALSE | AD2: a | AE2: 1 | AF2: 3 | AG2: 162 | AH2: 0 | AI2: 0 | AJ2: 0 | AK2: 0 | AL2: 0 | AM2: 27 | AN2: Raya | AS2: FALSE | AT2: p154561 | AU2: 3330 | AV2: 0 | AW2: 0 | AX2: 19 | AY2: 26 | AZ2: 0 | BA2: 0 | BB2: 0 | BC2: 1 | BD2: 0 | BE2: 60 | BF2: 11 | BG2: 633 | BH2: 541.6 | BI2: 33.5 | BJ2: 0 | BK2: 57.5 | BL2: 0 | BM2: 0 | BN2: 0 | BO2: 0 | BP2: 37 | BQ2: 0 | BR2: 0.07 | BS2: 0.07 | BT2: 27.56 | CC2: 96 | CD2: 16 | CE2: 304 | CF2: 3 | CG2: 549 | CH2: 60 | CI2: 229 | CJ2: 16 | CK2: 0 | CL2: 1.62 | CM2: 0 | CN2: 0 | CO2: 0.74 | CP2: 0.7 | CQ2: 60 | CR2: 1 | CS2: 454 | CT2: 60 | CU2: 32 | CV2: 3 | CW2: 6 | CX2: 1 | CY2: 1 | CZ2: 0.51 | DA2: 0
A3: TRUE | B3: TRUE | E3: 109745 | F3: 0 | G3: 0 | H3: 0 | I3: 0 | J3: 0 | K3: 0 | L3: 1 | M3: 2.6 | O3: 0 | P3: Kepa | Q3: 0 | R3: 2 | S3: FALSE | V3: 50 | W3: 109745.jpg | X3: 2 | Y3: FALSE | Z3: Arrizabalaga Revuelta | AA3: 0.3 | AB3: FALSE | AD3: a | AE3: 1 | AF3: 3 | AG3: 2 | AH3: 0 | AI3: 0 | AJ3: 0 | AK3: 0 | AL3: 0 | AM3: 0.4 | AN3: Arrizabalaga | AS3: FALSE | AT3: p109745 | AU3: 90 | AV3: 0 | AW3: 0 | AX3: 0 | AY3: 1 | AZ3: 0 | BA3: 0 | BB3: 0 | BC3: 0 | BD3: 0 | BE3: 2 | BF3: 0 | BG3: 11 | BH3: 19.8 | BI3: 0 | BJ3: 0 | BK3: 2 | BL3: 0 | BM3: 0 | BN3: 0 | BO3: 0 | BP3: 1 | BQ3: 0 | BR3: 0 | BS3: 0 | BT3: 0.98 | CC3: 357 | CD3: 30 | CE3: 486 | CF3: 54 | CG3: 480 | CH3: 49 | CI3: 373 | CJ3: 30 | CK3: 0 | CL3: 2 | CM3: 0 | CN3: 0 | CO3: 0.98 | CP3: 1 | CQ3: 222 | CR3: 8 | CS3: 200 | CT3: 46 | CU3: 285 | CV3: 28 | CW3: 315 | CX3: 37 | CY3: 1 | CZ3: 0 | DA3: 0
A4: TRUE | B4: TRUE | E4: 437495 | F4: 0 | G4: 0 | H4: 0 | I4: 0 | J4: 0 | K4: 0 | L4: 1 | M4: 2.6 | O4: 0 | P4: Illan | Q4: 0 | R4: 3 | S4: FALSE | V4: 50 | W4: 437495.jpg | X4: 0 | Y4: FALSE | Z4: Meslier | AA4: 0.1 | AB4: FALSE | AD4: a | AE4: 1 | AF4: 3 | AG4: 0 | AH4: 0 | AI4: 0 | AJ4: 0 | AK4: 0 | AL4: 0 | AM4: 0 | AN4: Meslier | AS4: FALSE | AT4: p437495 | AU4: 0 | AV4: 11 | AW4: 0 | AX4: 0 | AY4: 0 | AZ4: 0 | BA4: 0 | BB4: 0 | BC4: 0 | BD4: 0 | BE4: 0 | BF4: 0 | BG4: 11 | BH4: 0 | BI4: 0 | BJ4: 0 | BK4: 0 | BL4: 0 | BM4: 0 | BN4: 0 | BO4: 0 | BP4: 0 | BQ4: 0 | BR4: 0 | BS4: 0 | BT4: 0 | CC4: 508 | CD4: 60 | CE4: 505 | CF4: 57 | CG4: 502 | CH4: 55 | CI4: 508 | CJ4: 60 | CK4: 0 | CL4: 0 | CM4: 0 | CN4: 0 | CO4: 0 | CP4: 0 | CQ4: 285 | CR4: 14 | CS4: 263 | CT4: 52 | CU4: 508 | CV4: 60 | CW4: 431 | CX4: 52 | CY4: 0 | CZ4: 0 | DA4: 0
A5: TRUE | B5: TRUE | E5: 226597 | F5: 0 | G5: 0 | H5: 0 | I5: 0 | J5: 0 | K5: 0 | L5: 2 | M5: 4 | O5: 0 | P5: Gabriel | Q5: 0 | R5: 4 | S5: FALSE | V5: 80 | W5: 226597.jpg | X5: 6.5 | Y5: FALSE | Z5: dos Santos Magalhães | AA5: 24.2 | AB5: FALSE | AD5: a | AE5: 1 | AF5: 3 | AG5: 209 | AH5: 0 | AI5: 0 | AJ5: 0 | AK5: 0 | AL5: 0 | AM5: 26.1 | AN5: Gabriel | AS5: FALSE | AT5: p226597 | AU5: 2750 | AV5: 3 | AW5: 5 | AX5: 18 | AY5: 20 | AZ5: 0 | BA5: 0 | BB5: 0 | BC5: 4 | BD5: 0 | BE5: 0 | BF5: 30 | BG5: 724 | BH5: 824 | BI5: 128.5 | BJ5: 298 | BK5: 125 | BL5: 0 | BM5: 0 | BN5: 0 | BO5: 0 | BP5: 30 | BQ5: 2.94 | BR5: 1.75 | BS5: 4.69 | BT5: 22.01 | CC5: 25 | CD5: 9 | CE5: 219 | CF5: 61 | CG5: 101 | CH5: 15 | CI5: 80 | CJ5: 18 | CK5: 0.1 | CL5: 0 | CM5: 0.06 | CN5: 0.16 | CO5: 0.72 | CP5: 0.65 | CQ5: 9 | CR5: 1 | CS5: 549 | CT5: 184 | CU5: 4 | CV5: 1 | CW5: 9 | CX5: 3 | CY5: 0.98 | CZ5: 0.59 | DA5: 0
A6: TRUE | B6: TRUE | C6: 0 | E6: 445122 | F6: 0 | G6: 0 | H6: 0 | I6: 0 | J6: 0 | K6: 0 | L6: 2 | M6: 0 | O6: 0 | P6: Jurriën | Q6: 0 | R6: 5 | S6: FALSE | T6: Groin injury - Expected back 21 Aug | U6: 2026-07-23T12:01:23.272929Z | V6: 65 | W6: 445122.jpg | X6: 5 | Y6: FALSE | Z6: Timber | AA6: 0.9 | AB6: FALSE | AD6: i | AE6: 1 | AF6: 3 | AG6: 149 | AH6: 0 | AI6: 0 | AJ6: 0 | AK6: 0 | AL6: 0 | AM6: 22.9 | AN6: J.Timber | AS6: FALSE | AT6: p445122 | AU6: 2452 | AV6: 3 | AW6: 6 | AX6: 13 | AY6: 20 | AZ6: 0 | BA6: 0 | BB6: 0 | BC6: 5 | BD6: 0 | BE6: 0 | BF6: 9 | BG6: 532 | BH6: 499 | BI6: 402.6 | BJ6: 352 | BK6: 125.7 | BL6: 0 | BM6: 0 | BN6: 0 | BO6: 0 | BP6: 28 | BQ6: 4.71 | BR6: 1.53 | BS6: 6.24 | BT6: 17.45 | CB6: https://x.com/onsoranje/status/2064038072455495714?utm_source=premier-league-web&utm_medium=referral&utm_campaign=pl-referral-always-on&utm_term=injuries&utm_content=club-injury-article | CC6: 114 | CD6: 49 | CE6: 76 | CF6: 18 | CG6: 76 | CH6: 9 | CI6: 79 | CJ6: 17 | CK6: 0.17 | CL6: 0 | CM6: 0.06 | CN6: 0.23 | CO6: 0.64 | CP6: 0.73 | CQ6: 47 | CR6: 3 | CS6: 520 | CT6: 182 | CU6: 13 | CV6: 3 | CW6: 205 | CX6: 72 | CY6: 1.03 | CZ6: 0.48 | DA6: 0
A7: TRUE | B7: TRUE | C7: 0 | E7: 462424 | F7: 0 | G7: 0 | H7: 0 | I7: 0 | J7: 0 | K7: 0 | L7: 2 | M7: 0 | O7: 0 | P7: William | Q7: 0 | R7: 6 | S7: FALSE | T7: Back injury - Unknown return date | U7: 2026-07-23T12:01:23.289376Z | V7: 60 | W7: 462424.jpg | X7: 4.4 | Y7: FALSE | Z7: Saliba | AA7: 0.5 | AB7: FALSE | AD7: i | AE7: 1 | AF7: 3 | AG7: 137 | AH7: 0 | AI7: 0 | AJ7: 0 | AK7: 0 | AL7: 0 | AM7: 22.8 | AN7: Saliba | AS7: FALSE | AT7: p462424 | AU7: 2614 | AV7: 1 | AW7: 0 | AX7: 15 | AY7: 20 | AZ7: 0 | BA7: 0 | BB7: 0 | BC7: 2 | BD7: 0 | BE7: 0 | BF7: 12 | BG7: 581 | BH7: 552.6 | BI7: 201 | BJ7: 90 | BK7: 84.3 | BL7: 0 | BM7: 0 | BN7: 0 | BO7: 0 | BP7: 30 | BQ7: 0.88 | BR7: 1.21 | BS7: 2.09 | BT7: 20.41 | CB7: https://www.arsenal.com/news/medical-update-william-saliba-aVUca3q2han2 | CC7: 92 | CD7: 41 | CE7: 167 | CF7: 41 | CG7: 245 | CH7: 76 | CI7: 164 | CJ7: 57 | CK7: 0.03 | CL7: 0 | CM7: 0.04 | CN7: 0.07 | CO7: 0.7 | CP7: 0.69 | CQ7: 88 | CR7: 9 | CS7: 482 | CT7: 179 | CU7: 34 | CV7: 13 | CW7: 266 | CX7: 97 | CY7: 1.03 | CZ7: 0.52 | DA7: 0
A8: TRUE | B8: TRUE | E8: 499169 | F8: 0 | G8: 0 | H8: 0 | I8: 0 | J8: 0 | K8: 0 | L8: 3 | M8: 2 | O8: 0 | P8: Myles | Q8: 0 | R8: 7 | S8: FALSE | V8: 55 | W8: 499169.jpg | X8: 1.4 | Y8: FALSE | Z8: Lewis-Skelly | AA8: 0.3 | AB8: FALSE | AD8: a | AE8: 1 | AF8: 3 | AG8: 29 | AH8: 0 | AI8: 0 | AJ8: 0 | AK8: 0 | AL8: 0 | AM8: 5.3 | AN8: Lewis-Skelly | AS8: FALSE | AT8: p499169 | AU8: 697 | AV8: 0 | AW8: 0 | AX8: 2 | AY8: 8 | AZ8: 0 | BA8: 0 | BB8: 0 | BC8: 3 | BD8: 0 | BE8: 0 | BF8: 0 | BG8: 110 | BH8: 73.2 | BI8: 74.6 | BJ8: 29 | BK8: 17.6 | BL8: 0 | BM8: 0 | BN8: 0 | BO8: 0 | BP8: 5 | BQ8: 0.1 | BR8: 0.2 | BS8: 0.3 | BT8: 9.01 | CC8: 318 | CD8: 144 | CE8: 262 | CF8: 145 | CG8: 302 | CH8: 157 | CI8: 315 | CJ8: 150 | CK8: 0.01 | CL8: 0 | CM8: 0.03 | CN8: 0.04 | CO8: 1.16 | CP8: 1.03 | CQ8: 188 | CR8: 116 | CS8: 425 | CT8: 159 | CU8: 341 | CV8: 155 | CW8: 310 | CX8: 107 | CY8: 0.65 | CZ8: 0.26 | DA8: 0
A9: TRUE | B9: TRUE | E9: 466075 | F9: 0 | G9: 0 | H9: 0 | I9: 0 | J9: 0 | K9: 0 | L9: 2 | M9: 2.5 | O9: 0 | P9: Riccardo | Q9: 0 | R9: 8 | S9: FALSE | V9: 55 | W9: 466075.jpg | X9: 4.2 | Y9: FALSE | Z9: Calafiori | AA9: 11.5 | AB9: FALSE | AD9: a | AE9: 1 | AF9: 3 | AG9: 109 | AH9: 0 | AI9: 0 | AJ9: 0 | AK9: 0 | AL9: 0 | AM9: 19.8 | AN9: Calafiori | AS9: FALSE | AT9: p466075 | AU9: 1697 | AV9: 1 | AW9: 2 | AX9: 13 | AY9: 8 | AZ9: 0 | BA9: 0 | BB9: 0 | BC9: 5 | BD9: 0 | BE9: 0 | BF9: 6 | BG9: 389 | BH9: 283 | BI9: 182.3 | BJ9: 313 | BK9: 77.9 | BL9: 0 | BM9: 0 | BN9: 0 | BO9: 0 | BP9: 22 | BQ9: 3.36 | BR9: 0.76 | BS9: 4.12 | BT9: 9.72 | CC9: 211 | CD9: 80 | CE9: 182 | CF9: 46 | CG9: 93 | CH9: 12 | CI9: 178 | CJ9: 62 | CK9: 0.18 | CL9: 0 | CM9: 0.04 | CN9: 0.22 | CO9: 0.52 | CP9: 0.42 | CQ9: 173 | CR9: 24 | CS9: 410 | CT9: 166 | CU9: 41 | CV9: 16 | CW9: 41 | CX9: 15 | CY9: 1.17 | CZ9: 0.69 | DA9: 0
A10: TRUE | B10: TRUE | E10: 448104 | F10: 0 | G10: 0 | H10: 0 | I10: 0 | J10: 0 | K10: 0 | L10: 2 | M10: 2.5 | O10: 0 | P10: Piero | Q10: 0 | R10: 9 | S10: FALSE | V10: 55 | W10: 448104.jpg | X10: 3.5 | Y10: FALSE | Z10: Hincapié | AA10: 6.1 | AB10: FALSE | AD10: a | AE10: 1 | AF10: 3 | AG10: 87 | AH10: 0 | AI10: 0 | AJ10: 0 | AK10: 0 | AL10: 0 | AM10: 15.8 | AN10: Hincapie | AS10: FALSE | AT10: p448104 | AU10: 1787 | AV10: 1 | AW10: 2 | AX10: 5 | AY10: 19 | AZ10: 1 | BA10: 0 | BB10: 0 | BC10: 2 | BD10: 0 | BE10: 0 | BF10: 7 | BG10: 335 | BH10: 453.6 | BI10: 184.7 | BJ10: 72 | BK10: 70.9 | BL10: 0 | BM10: 0 | BN10: 0 | BO10: 0 | BP10: 20 | BQ10: 0.36 | BR10: 1.67 | BS10: 2.03 | BT10: 17.53 | CC10: 129 | CD10: 54 | CE10: 180 | CF10: 45 | CG10: 258 | CH10: 82 | CI10: 196 | CJ10: 65 | CK10: 0.02 | CL10: 0 | CM10: 0.08 | CN10: 0.1 | CO10: 0.88 | CP10: 0.96 | CQ10: 164 | CR10: 21 | CS10: 401 | CT10: 163 | CU10: 105 | CV10: 43 | CW10: 68 | CX10: 27 | CY10: 1.01 | CZ10: 0.25 | DA10: 0
A11: TRUE | B11: TRUE | C11: 0 | E11: 198869 | F11: 0 | G11: 0 | H11: 0 | I11: 0 | J11: 0 | K11: 0 | L11: 2 | M11: 0 | O11: 0 | P11: Benjamin | Q11: 0 | R11: 10 | S11: FALSE | T11: Knee injury - Expected back 21 Aug | U11: 2026-07-23T12:01:23.305229Z | V11: 55 | W11: 198869.jpg | X11: 3.8 | Y11: FALSE | Z11: White | AA11: 0 | AB11: FALSE | AD11: i | AE11: 1 | AF11: 3 | AG11: 45 | AH11: 0 | AI11: 0 | AJ11: 0 | AK11: 0 | AL11: 0 | AM11: 8.2 | AN11: White | AS11: FALSE | AT11: p198869 | AU11: 699 | AV11: 0 | AW11: 1 | AX11: 5 | AY11: 6 | AZ11: 0 | BA11: 0 | BB11: 0 | BC11: 0 | BD11: 0 | BE11: 0 | BF11: 3 | BG11: 181 | BH11: 154.8 | BI11: 133.4 | BJ11: 54 | BK11: 34.3 | BL11: 0 | BM11: 0 | BN11: 0 | BO11: 0 | BP11: 9 | BQ11: 0.45 | BR11: 0.69 | BS11: 1.14 | BT11: 8.68 | CC11: 272 | CD11: 101 | CE11: 213 | CF11: 58 | CG11: 275 | CH11: 89 | CI11: 280 | CJ11: 92 | CK11: 0.06 | CL11: 0 | CM11: 0.09 | CN11: 0.15 | CO11: 1.12 | CP11: 0.77 | CQ11: 127 | CR11: 13 | CS11: 364 | CT11: 155 | CU11: 71 | CV11: 27 | CW11: 527 | CX11: 179 | CY11: 1.16 | CZ11: 0.64 | DA11: 0
A12: TRUE | B12: TRUE | E12: 500040 | F12: 0 | G12: 0 | H12: 0 | I12: 0 | J12: 0 | K12: 0 | L12: 2 | M12: 2.5 | O12: 0 | P12: Cristhian | Q12: 0 | R12: 11 | S12: FALSE | V12: 55 | W12: 500040.jpg | X12: 2 | Y12: FALSE | Z12: Mosquera | AA12: 14.9 | AB12: FALSE | AD12: a | AE12: 1 | AF12: 3 | AG12: 40 | AH12: 0 | AI12: 0 | AJ12: 0 | AK12: 0 | AL12: 0 | AM12: 7.3 | AN12: Mosquera | AS12: FALSE | AT12: p500040 | AU12: 986 | AV12: 0 | AW12: 0 | AX12: 3 | AY12: 8 | AZ12: 0 | BA12: 0 | BB12: 0 | BC12: 4 | BD12: 0 | BE12: 0 | BF12: 1 | BG12: 195 | BH12: 219.2 | BI12: 88.7 | BJ12: 20 | BK12: 32.9 | BL12: 0 | BM12: 0 | BN12: 0 | BO12: 0 | BP12: 9 | BQ12: 0.1 | BR12: 0.63 | BS12: 0.73 | BT12: 9.04 | CC12: 239 | CD12: 90 | CE12: 243 | CF12: 79 | CG12: 310 | CH12: 108 | CI12: 282 | CJ12: 93 | CK12: 0.01 | CL12: 0 | CM12: 0.06 | CN12: 0.07 | CO12: 0.83 | CP12: 0.73 | CQ12: 190 | CR12: 28 | CS12: 427 | CT12: 170 | CU12: 288 | CV12: 110 | CW12: 27 | CX12: 10 | CY12: 0.82 | CZ12: 0.27 | DA12: 0
A13: TRUE | B13: TRUE | E13: 223340 | F13: 0 | G13: 0 | H13: 0 | I13: 0 | J13: 0 | K13: 0 | L13: 3 | M13: 3.2 | O13: 0 | P13: Bukayo | Q13: 0 | R13: 12 | S13: FALSE | V13: 95 | W13: 223340.jpg | X13: 5.1 | Y13: FALSE | Z13: Saka | AA13: 11.3 | AB13: FALSE | AD13: a | AE13: 1 | AF13: 3 | AG13: 157 | AH13: 0 | AI13: 0 | AJ13: 0 | AK13: 0 | AL13: 0 | AM13: 16.5 | AN13: Saka | AS13: FALSE | AT13: p223340 | AU13: 2218 | AV13: 7 | AW13: 10 | AX13: 12 | AY13: 16 | AZ13: 0 | BA13: 0 | BB13: 0 | BC13: 2 | BD13: 0 | BE13: 0 | BF13: 18 | BG13: 570 | BH13: 627 | BI13: 847.6 | BJ13: 828 | BK13: 230.6 | BL13: 0 | BM13: 0 | BN13: 0 | BO13: 0 | BP13: 25 | BQ13: 7.57 | BR13: 7.16 | BS13: 14.73 | BT13: 15.57 | BU13: 6 | BW13: 2 | BY13: 1 | CC13: 68 | CD13: 20 | CE13: 12 | CF13: 11 | CG13: 11 | CH13: 6 | CI13: 10 | CJ13: 8 | CK13: 0.31 | CL13: 0 | CM13: 0.29 | CN13: 0.6 | CO13: 0.63 | CP13: 0.65 | CQ13: 3 | CR13: 2 | CS13: 555 | CT13: 244 | CU13: 12 | CV13: 6 | CW13: 42 | CX13: 14 | CY13: 1.01 | CZ13: 0.49 | DA13: 0
A14: TRUE | B14: TRUE | E14: 204480 | F14: 0 | G14: 0 | H14: 0 | I14: 0 | J14: 0 | K14: 0 | L14: 3 | M14: 2.6 | O14: 0 | P14: Declan | Q14: 0 | R14: 13 | S14: FALSE | V14: 75 | W14: 204480.jpg | X14: 5.1 | Y14: FALSE | Z14: Rice | AA14: 23.1 | AB14: FALSE | AD14: a | AE14: 1 | AF14: 3 | AG14: 184 | AH14: 0 | AI14: 0 | AJ14: 0 | AK14: 0 | AL14: 0 | AM14: 24.5 | AN14: Rice | AS14: FALSE | AT14: p204480 | AU14: 3093 | AV14: 4 | AW14: 9 | AX14: 18 | AY14: 25 | AZ14: 0 | BA14: 0 | BB14: 0 | BC14: 3 | BD14: 0 | BE14: 0 | BF14: 23 | BG14: 790 | BH14: 827.2 | BI14: 1027.4 | BJ14: 298 | BK14: 215.4 | BL14: 0 | BM14: 0 | BN14: 0 | BO14: 0 | BP14: 35 | BQ14: 3.15 | BR14: 7.32 | BS14: 10.47 | BT14: 23.87 | BU14: 5 | BW14: 1 | CC14: 24 | CD14: 8 | CE14: 4 | CF14: 4 | CG14: 100 | CH14: 63 | CI14: 14 | CJ14: 11 | CK14: 0.09 | CL14: 0 | CM14: 0.21 | CN14: 0.3 | CO14: 0.69 | CP14: 0.73 | CQ14: 13 | CR14: 8 | CS14: 537 | CT14: 234 | CU14: 9 | CV14: 4 | CW14: 12 | CX14: 4 | CY14: 1.02 | CZ14: 0.52 | DA14: 0
A15: TRUE | B15: TRUE | E15: 232413 | F15: 0 | G15: 0 | H15: 0 | I15: 0 | J15: 0 | K15: 0 | L15: 3 | M15: 2.3 | O15: 0 | P15: Eberechi | Q15: 0 | R15: 14 | S15: FALSE | V15: 65 | W15: 232413.jpg | X15: 3.4 | Y15: FALSE | Z15: Eze | AA15: 3.1 | AB15: FALSE | AD15: a | AE15: 1 | AF15: 3 | AG15: 113 | AH15: 0 | AI15: 0 | AJ15: 0 | AK15: 0 | AL15: 0 | AM15: 17.4 | AN15: Eze | AS15: FALSE | AT15: p232413 | AU15: 1885 | AV15: 7 | AW15: 3 | AX15: 11 | AY15: 14 | AZ15: 0 | BA15: 0 | BB15: 0 | BC15: 1 | BD15: 0 | BE15: 0 | BF15: 8 | BG15: 439 | BH15: 393.4 | BI15: 305.7 | BJ15: 455 | BK15: 115.1 | BL15: 0 | BM15: 0 | BN15: 0 | BO15: 0 | BP15: 22 | BQ15: 5.18 | BR15: 2.66 | BS15: 7.84 | BT15: 14.21 | BW15: 3 | CC15: 156 | CD15: 61 | CE15: 123 | CF15: 85 | CG15: 47 | CH15: 28 | CI15: 95 | CJ15: 54 | CK15: 0.25 | CL15: 0 | CM15: 0.13 | CN15: 0.38 | CO15: 0.68 | CP15: 0.67 | CQ15: 41 | CR15: 28 | CS15: 514 | CT15: 216 | CU15: 122 | CV15: 50 | CW15: 102 | CX15: 33 | CY15: 1.05 | CZ15: 0.53 | DA15: 0
A16: TRUE | B16: TRUE | E16: 184029 | F16: 0 | G16: 0 | H16: 0 | I16: 0 | J16: 0 | K16: 0 | L16: 3 | M16: 2.3 | O16: 0 | P16: Martin | Q16: 0 | R16: 15 | S16: FALSE | V16: 65 | W16: 184029.jpg | X16: 3.1 | Y16: FALSE | Z16: Ødegaard | AA16: 2.7 | AB16: FALSE | AD16: a | AE16: 1 | AF16: 3 | AG16: 74 | AH16: 0 | AI16: 0 | AJ16: 0 | AK16: 0 | AL16: 0 | AM16: 11.4 | AN16: Ødegaard | AS16: FALSE | AT16: p184029 | AU16: 1363 | AV16: 1 | AW16: 7 | AX16: 6 | AY16: 13 | AZ16: 0 | BA16: 0 | BB16: 0 | BC16: 0 | BD16: 0 | BE16: 0 | BF16: 5 | BG16: 306 | BH16: 311.8 | BI16: 564.4 | BJ16: 168 | BK16: 104.4 | BL16: 0 | BM16: 0 | BN16: 0 | BO16: 0 | BP16: 16 | BQ16: 1.25 | BR16: 3.65 | BS16: 4.9 | BT16: 16.2 | BU16: 8 | BY16: 3 | CC16: 196 | CD16: 85 | CE16: 39 | CF16: 36 | CG16: 180 | CH16: 98 | CI16: 120 | CJ16: 68 | CK16: 0.08 | CL16: 0 | CM16: 0.24 | CN16: 0.32 | CO16: 1.07 | CP16: 0.86 | CQ16: 35 | CR16: 23 | CS16: 508 | CT16: 211 | CU16: 163 | CV16: 62 | CW16: 109 | CX16: 35 | CY16: 1.06 | CZ16: 0.4 | DA16: 0
A17: TRUE | B17: TRUE | E17: 248857 | F17: 0 | G17: 0 | H17: 0 | I17: 0 | J17: 0 | K17: 0 | L17: 3 | M17: 2.3 | O17: 0 | P17: Noni | Q17: 0 | R17: 16 | S17: FALSE | V17: 65 | W17: 248857.jpg | X17: 2.8 | Y17: FALSE | Z17: Madueke | AA17: 0.3 | AB17: FALSE | AD17: a | AE17: 1 | AF17: 3 | AG17: 72 | AH17: 0 | AI17: 0 | AJ17: 0 | AK17: 0 | AL17: 0 | AM17: 11.1 | AN17: Madueke | AS17: FALSE | AT17: p248857 | AU17: 1205 | AV17: 3 | AW17: 1 | AX17: 8 | AY17: 9 | AZ17: 0 | BA17: 0 | BB17: 0 | BC17: 0 | BD17: 0 | BE17: 0 | BF17: 9 | BG17: 254 | BH17: 257.4 | BI17: 352.8 | BJ17: 404 | BK17: 101.3 | BL17: 0 | BM17: 0 | BN17: 0 | BO17: 0 | BP17: 16 | BQ17: 1.23 | BR17: 2.86 | BS17: 4.09 | BT17: 12.77 | BU17: 7 | CC17: 221 | CD17: 98 | CE17: 98 | CF17: 71 | CG17: 64 | CH17: 38 | CI17: 126 | CJ17: 72 | CK17: 0.09 | CL17: 0 | CM17: 0.21 | CN17: 0.3 | CO17: 0.95 | CP17: 0.67 | CQ17: 43 | CR17: 30 | CS17: 516 | CT17: 218 | CU17: 201 | CV17: 77 | CW17: 307 | CX17: 105 | CY17: 1.2 | CZ17: 0.6 | DA17: 0
A18: TRUE | B18: TRUE | E18: 195384 | F18: 0 | G18: 0 | H18: 0 | I18: 0 | J18: 0 | K18: 0 | L18: 3 | M18: 2.1 | O18: 0 | P18: Mikel | Q18: 0 | R18: 17 | S18: FALSE | V18: 60 | W18: 195384.jpg | X18: 3 | Y18: FALSE | Z18: Merino Zazón | AA18: 1.1 | AB18: FALSE | AD18: a | AE18: 1 | AF18: 3 | AG18: 67 | AH18: 0 | AI18: 0 | AJ18: 0 | AK18: 0 | AL18: 0 | AM18: 11.2 | AN18: Merino | AS18: FALSE | AT18: p195384 | AU18: 1024 | AV18: 4 | AW18: 3 | AX18: 4 | AY18: 10 | AZ18: 0 | BA18: 0 | BB18: 0 | BC18: 1 | BD18: 0 | BE18: 0 | BF18: 5 | BG18: 236 | BH18: 304.4 | BI18: 191.8 | BJ18: 244 | BK18: 73.6 | BL18: 0 | BM18: 0 | BN18: 0 | BO18: 0 | BP18: 10 | BQ18: 3.36 | BR18: 1.45 | BS18: 4.81 | BT18: 7.36 | CC18: 199 | CD18: 88 | CE18: 176 | CF18: 118 | CG18: 119 | CH18: 69 | CI18: 189 | CJ18: 94 | CK18: 0.3 | CL18: 0 | CM18: 0.13 | CN18: 0.43 | CO18: 0.65 | CP18: 0.88 | CQ18: 64 | CR18: 42 | CS18: 458 | CT18: 177 | CU18: 175 | CV18: 68 | CW18: 185 | CX18: 61 | CY18: 0.88 | CZ18: 0.35 | DA18: 0
A19: TRUE | B19: TRUE | E19: 444145 | F19: 0 | G19: 0 | H19: 0 | I19: 0 | J19: 0 | K19: 0 | L19: 3 | M19: 2.3 | O19: 0 | P19: Gabriel | Q19: 0 | R19: 18 | S19: FALSE | V19: 65 | W19: 444145.jpg | X19: 1.9 | Y19: FALSE | Z19: Martinelli Silva | AA19: 0.3 | AB19: FALSE | AD19: a | AE19: 1 | AF19: 3 | AG19: 57 | AH19: 0 | AI19: 0 | AJ19: 0 | AK19: 0 | AL19: 0 | AM19: 8.8 | AN19: Martinelli | AS19: FALSE | AT19: p444145 | AU19: 1065 | AV19: 1 | AW19: 5 | AX19: 2 | AY19: 8 | AZ19: 0 | BA19: 0 | BB19: 0 | BC19: 3 | BD19: 0 | BE19: 0 | BF19: 3 | BG19: 195 | BH19: 204.6 | BI19: 202.2 | BJ19: 390 | BK19: 79 | BL19: 0 | BM19: 0 | BN19: 0 | BO19: 0 | BP19: 11 | BQ19: 4.12 | BR19: 1.27 | BS19: 5.39 | BT19: 10.51 | CC19: 249 | CD19: 112 | CE19: 166 | CF19: 111 | CG19: 69 | CH19: 42 | CI19: 177 | CJ19: 86 | CK19: 0.35 | CL19: 0 | CM19: 0.11 | CN19: 0.46 | CO19: 0.89 | CP19: 0.68 | CQ19: 45 | CR19: 32 | CS19: 518 | CT19: 220 | CU19: 298 | CV19: 130 | CW19: 317 | CX19: 112 | CY19: 0.93 | CZ19: 0.17 | DA19: 0
A20: TRUE | B20: TRUE | E20: 481655 | F20: 0 | G20: 0 | H20: 0 | I20: 0 | J20: 0 | K20: 0 | L20: 3 | M20: 2 | O20: 0 | P20: Martín | Q20: 0 | R20: 19 | S20: FALSE | V20: 55 | W20: 481655.jpg | X20: 3.5 | Y20: FALSE | Z20: Zubimendi Ibáñez | AA20: 1.3 | AB20: FALSE | AD20: a | AE20: 1 | AF20: 3 | AG20: 133 | AH20: 0 | AI20: 0 | AJ20: 0 | AK20: 0 | AL20: 0 | AM20: 24.2 | AN20: Zubimendi | AS20: FALSE | AT20: p481655 | AU20: 2991 | AV20: 5 | AW20: 1 | AX20: 16 | AY20: 25 | AZ20: 0 | BA20: 0 | BB20: 0 | BC20: 4 | BD20: 0 | BE20: 0 | BF20: 9 | BG20: 604 | BH20: 603.2 | BI20: 385.1 | BJ20: 271 | BK20: 126.2 | BL20: 0 | BM20: 0 | BN20: 0 | BO20: 0 | BP20: 34 | BQ20: 2.84 | BR20: 2.27 | BS20: 5.11 | BT20: 26.09 | CC20: 74 | CD20: 24 | CE20: 85 | CF20: 63 | CG20: 110 | CH20: 64 | CI20: 78 | CJ20: 49 | CK20: 0.09 | CL20: 0 | CM20: 0.07 | CN20: 0.16 | CO20: 0.79 | CP20: 0.75 | CQ20: 180 | CR20: 110 | CS20: 417 | CT20: 153 | CU20: 107 | CV20: 42 | CW20: 173 | CX20: 57 | CY20: 1.02 | CZ20: 0.48 | DA20: 0
A21: TRUE | B21: TRUE | E21: 616077 | F21: 0 | G21: 0 | H21: 0 | I21: 0 | J21: 0 | K21: 0 | L21: 3 | M21: 2 | O21: 0 | P21: Max | Q21: 0 | R21: 20 | S21: FALSE | V21: 55 | W21: 616077.jpg | X21: 2.7 | Y21: FALSE | Z21: Dowman | AA21: 0.2 | AB21: FALSE | AD21: a | AE21: 1 | AF21: 3 | AG21: 16 | AH21: 0 | AI21: 0 | AJ21: 0 | AK21: 0 | AL21: 0 | AM21: 2.9 | AN21: Dowman | AS21: FALSE | AT21: p616077 | AU21: 152 | AV21: 1 | AW21: 1 | AX21: 1 | AY21: 1 | AZ21: 0 | BA21: 0 | BB21: 0 | BC21: 0 | BD21: 0 | BE21: 0 | BF21: 0 | BG21: 51 | BH21: 45.2 | BI21: 55.5 | BJ21: 65 | BK21: 16.6 | BL21: 0 | BM21: 0 | BN21: 0 | BO21: 0 | BP21: 1 | BQ21: 1.19 | BR21: 0.3 | BS21: 1.49 | BT21: 0.88 | CC21: 338 | CD21: 154 | CE21: 279 | CF21: 153 | CG21: 264 | CH21: 140 | CI21: 318 | CJ21: 152 | CK21: 0.7 | CL21: 0 | CM21: 0.18 | CN21: 0.88 | CO21: 0.52 | CP21: 0.59 | CQ21: 210 | CR21: 131 | CS21: 447 | CT21: 174 | CU21: 212 | CV21: 83 | CW21: 383 | CX21: 143 | CY21: 0.59 | CZ21: 0.59 | DA21: 0
A22: TRUE | B22: TRUE | E22: 128295 | F22: 0 | G22: 0 | H22: 0 | I22: 0 | J22: 0 | K22: 0 | L22: 3 | M22: 1.5 | O22: 0 | P22: Christian | Q22: 0 | R22: 21 | S22: FALSE | V22: 50 | W22: 128295.jpg | X22: 1 | Y22: FALSE | Z22: Nørgaard | AA22: 0.1 | AB22: FALSE | AD22: a | AE22: 1 | AF22: 3 | AG22: 7 | AH22: 0 | AI22: 0 | AJ22: 0 | AK22: 0 | AL22: 0 | AM22: 1.4 | AN22: Nørgaard | AS22: FALSE | AT22: p128295 | AU22: 101 | AV22: 0 | AW22: 0 | AX22: 0 | AY22: 1 | AZ22: 0 | BA22: 0 | BB22: 0 | BC22: 0 | BD22: 0 | BE22: 0 | BF22: 0 | BG22: 28 | BH22: 23.4 | BI22: 5.5 | BJ22: 10 | BK22: 4 | BL22: 0 | BM22: 0 | BN22: 0 | BO22: 0 | BP22: 1 | BQ22: 0.08 | BR22: 0.04 | BS22: 0.12 | BT22: 2.28 | CC22: 354 | CD22: 164 | CE22: 353 | CF22: 174 | CG22: 327 | CH22: 167 | CI22: 363 | CJ22: 169 | CK22: 0.07 | CL22: 0 | CM22: 0.04 | CN22: 0.11 | CO22: 2.03 | CP22: 0.89 | CQ22: 225 | CR22: 136 | CS22: 203 | CT22: 30 | CU22: 377 | CV22: 173 | CW22: 446 | CX22: 174 | CY22: 0.89 | CZ22: 0 | DA22: 0
A23: TRUE | B23: TRUE | E23: 499175 | F23: 0 | G23: 0 | H23: 0 | I23: 0 | J23: 0 | K23: 0 | L23: 3 | M23: 2 | O23: 0 | P23: Ethan | Q23: 0 | R23: 22 | S23: FALSE | V23: 55 | W23: 499175.jpg | X23: 1.3 | Y23: FALSE | Z23: Nwaneri | AA23: 0 | AB23: FALSE | AD23: a | AE23: 1 | AF23: 3 | AG23: 8 | AH23: 0 | AI23: 0 | AJ23: 0 | AK23: 0 | AL23: 0 | AM23: 1.5 | AN23: Nwaneri | AS23: FALSE | AT23: p499175 | AU23: 165 | AV23: 0 | AW23: 0 | AX23: 1 | AY23: 0 | AZ23: 0 | BA23: 0 | BB23: 0 | BC23: 0 | BD23: 0 | BE23: 0 | BF23: 0 | BG23: 20 | BH23: 8.6 | BI23: 22.5 | BJ23: 24 | BK23: 5.4 | BL23: 0 | BM23: 0 | BN23: 0 | BO23: 0 | BP23: 0 | BQ23: 0.23 | BR23: 0.08 | BS23: 0.31 | BT23: 0.73 | CC23: 372 | CD23: 171 | CE23: 321 | CF23: 165 | CG23: 306 | CH23: 158 | CI23: 356 | CJ23: 166 | CK23: 0.13 | CL23: 0 | CM23: 0.04 | CN23: 0.17 | CO23: 0.4 | CP23: 0 | CQ23: 189 | CR23: 117 | CS23: 426 | CT23: 160 | CU23: 347 | CV23: 159 | CW23: 524 | CX23: 221 | CY23: 0 | CZ23: 0.55 | DA23: 0
A24: TRUE | B24: TRUE | E24: 438098 | F24: 0 | G24: 0 | H24: 0 | I24: 0 | J24: 0 | K24: 0 | L24: 3 | M24: 2 | O24: 0 | P24: Fábio | Q24: 0 | R24: 23 | S24: FALSE | V24: 55 | W24: 438098.jpg | X24: 0 | Y24: FALSE | Z24: Ferreira Vieira | AA24: 0 | AB24: FALSE | AD24: a | AE24: 1 | AF24: 3 | AG24: 0 | AH24: 0 | AI24: 0 | AJ24: 0 | AK24: 0 | AL24: 0 | AM24: 0 | AN24: Fábio Vieira | AS24: FALSE | AT24: p438098 | AU24: 0 | AV24: 0 | AW24: 0 | AX24: 0 | AY24: 0 | AZ24: 0 | BA24: 0 | BB24: 0 | BC24: 0 | BD24: 0 | BE24: 0 | BF24: 0 | BG24: 0 | BH24: 0 | BI24: 0 | BJ24: 0 | BK24: 0 | BL24: 0 | BM24: 0 | BN24: 0 | BO24: 0 | BP24: 0 | BQ24: 0 | BR24: 0 | BS24: 0 | BT24: 0 | CC24: 542 | CD24: 234 | CE24: 542 | CF24: 234 | CG24: 541 | CH24: 234 | CI24: 542 | CJ24: 234 | CK24: 0 | CL24: 0 | CM24: 0 | CN24: 0 | CO24: 0 | CP24: 0 | CQ24: 158 | CR24: 99 | CS24: 395 | CT24: 142 | CU24: 542 | CV24: 234 | CW24: 540 | CX24: 234 | CY24: 0 | CZ24: 0 | DA24: 0
A25: TRUE | B25: TRUE | E25: 200641 | F25: 0 | G25: 0 | H25: 0 | I25: 0 | J25: 0 | K25: 0 | L25: 3 | M25: 2 | O25: 0 | P25: Reiss | Q25: 0 | R25: 24 | S25: FALSE | V25: 55 | W25: 200641.jpg | X25: 1.3 | Y25: FALSE | Z25: Nelson | AA25: 0 | AB25: FALSE | AD25: a | AE25: 1 | AF25: 3 | AG25: 13 | AH25: 0 | AI25: 0 | AJ25: 0 | AK25: 0 | AL25: 0 | AM25: 2.4 | AN25: Nelson | AS25: FALSE | AT25: p200641 | AU25: 118 | AV25: 0 | AW25: 1 | AX25: 0 | AY25: 2 | AZ25: 0 | BA25: 0 | BB25: 0 | BC25: 0 | BD25: 0 | BE25: 0 | BF25: 0 | BG25: 39 | BH25: 42.6 | BI25: 32.6 | BJ25: 29 | BK25: 10 | BL25: 0 | BM25: 0 | BN25: 0 | BO25: 0 | BP25: 0 | BQ25: 0.71 | BR25: 0.11 | BS25: 0.82 | BT25: 3.02 | CC25: 340 | CD25: 156 | CE25: 306 | CF25: 161 | CG25: 301 | CH25: 156 | CI25: 337 | CJ25: 157 | CK25: 0.54 | CL25: 0 | CM25: 0.08 | CN25: 0.62 | CO25: 2.3 | CP25: 1.53 | CQ25: 129 | CR25: 81 | CS25: 366 | CT25: 124 | CU25: 345 | CV25: 157 | CW25: 539 | CX25: 233 | CY25: 0 | CZ25: 0 | DA25: 0
A26: TRUE | B26: TRUE | E26: 224117 | F26: 0 | G26: 0 | H26: 0 | I26: 0 | J26: 0 | K26: 0 | L26: 4 | M26: 2.3 | O26: 0 | P26: Viktor | Q26: 0 | R26: 25 | S26: FALSE | V26: 75 | W26: 224117.jpg | X26: 3.6 | Y26: FALSE | Z26: Gyökeres | AA26: 15.7 | AB26: FALSE | AD26: a | AE26: 1 | AF26: 3 | AG26: 128 | AH26: 0 | AI26: 0 | AJ26: 0 | AK26: 0 | AL26: 0 | AM26: 17.1 | AN26: Gyökeres | AS26: FALSE | AT26: p224117 | AU26: 2217 | AV26: 14 | AW26: 1 | AX26: 12 | AY26: 14 | AZ26: 0 | BA26: 0 | BB26: 0 | BC26: 5 | BD26: 0 | BE26: 0 | BF26: 16 | BG26: 474 | BH26: 539.6 | BI26: 271.7 | BJ26: 772 | BK26: 157.5 | BL26: 0 | BM26: 0 | BN26: 0 | BO26: 0 | BP26: 26 | BQ26: 12.26 | BR26: 1.94 | BS26: 14.19 | BT26: 17.81 | BY26: 2 | CC26: 99 | CD26: 9 | CE26: 133 | CF26: 11 | CG26: 19 | CH26: 11 | CI26: 46 | CJ26: 8 | CK26: 0.5 | CL26: 0 | CM26: 0.08 | CN26: 0.58 | CO26: 0.72 | CP26: 0.57 | CQ26: 15 | CR26: 6 | CS26: 539 | CT26: 62 | CU26: 97 | CV26: 10 | CW26: 24 | CX26: 6 | CY26: 1.06 | CZ26: 0.49 | DA26: 0
A27: TRUE | B27: TRUE | E27: 219847 | F27: 0 | G27: 0 | H27: 0 | I27: 0 | J27: 0 | K27: 0 | L27: 4 | M27: 2.3 | O27: 0 | P27: Kai | Q27: 0 | R27: 26 | S27: FALSE | V27: 75 | W27: 219847.jpg | X27: 3 | Y27: FALSE | Z27: Havertz | AA27: 5.2 | AB27: FALSE | AD27: a | AE27: 1 | AF27: 3 | AG27: 36 | AH27: 0 | AI27: 0 | AJ27: 0 | AK27: 0 | AL27: 0 | AM27: 4.8 | AN27: Havertz | AS27: FALSE | AT27: p219847 | AU27: 577 | AV27: 2 | AW27: 3 | AX27: 4 | AY27: 4 | AZ27: 0 | BA27: 0 | BB27: 0 | BC27: 1 | BD27: 0 | BE27: 0 | BF27: 3 | BG27: 143 | BH27: 152.6 | BI27: 134.6 | BJ27: 210 | BK27: 49.9 | BL27: 0 | BM27: 0 | BN27: 0 | BO27: 0 | BP27: 7 | BQ27: 3.31 | BR27: 0.64 | BS27: 3.95 | BT27: 6.68 | CC27: 274 | CD27: 27 | CE27: 211 | CF27: 23 | CG27: 145 | CH27: 32 | CI27: 245 | CJ27: 27 | CK27: 0.52 | CL27: 0 | CM27: 0.1 | CN27: 0.62 | CO27: 1.04 | CP27: 0.62 | CQ27: 14 | CR27: 5 | CS27: 538 | CT27: 61 | CU27: 177 | CV27: 17 | CW27: 76 | CX27: 11 | CY27: 1.09 | CZ27: 0.62 | DA27: 0
A28: TRUE | B28: TRUE | E28: 205651 | F28: 0 | G28: 0 | H28: 0 | I28: 0 | J28: 0 | K28: 0 | L28: 4 | M28: 2 | O28: 0 | P28: Gabriel | Q28: 0 | R28: 27 | S28: FALSE | V28: 60 | W28: 205651.jpg | X28: 1.7 | Y28: FALSE | Z28: Fernando de Jesus | AA28: 0.3 | AB28: FALSE | AD28: a | AE28: 1 | AF28: 3 | AG28: 24 | AH28: 0 | AI28: 0 | AJ28: 0 | AK28: 0 | AL28: 0 | AM28: 4 | AN28: G.Jesus | AS28: FALSE | AT28: p205651 | AU28: 418 | AV28: 3 | AW28: 0 | AX28: 1 | AY28: 6 | AZ28: 0 | BA28: 0 | BB28: 0 | BC28: 3 | BD28: 0 | BE28: 0 | BF28: 0 | BG28: 92 | BH28: 141.8 | BI28: 54.3 | BJ28: 281 | BK28: 47.5 | BL28: 0 | BM28: 0 | BN28: 0 | BO28: 0 | BP28: 3 | BQ28: 2.71 | BR28: 0.26 | BS28: 2.97 | BT28: 3.97 | CC28: 280 | CD28: 30 | CE28: 281 | CF28: 33 | CG28: 107 | CH28: 27 | CI28: 252 | CJ28: 30 | CK28: 0.58 | CL28: 0 | CM28: 0.06 | CN28: 0.64 | CO28: 0.85 | CP28: 1.29 | CQ28: 68 | CR28: 17 | CS28: 462 | CT28: 47 | CU28: 319 | CV28: 35 | CW28: 322 | CX28: 57 | CY28: 0.65 | CZ28: 0.22 | DA28: 0
A29: TRUE | B29: TRUE | E29: 439509 | F29: 0 | G29: 0 | H29: 0 | I29: 0 | J29: 0 | K29: 0 | L29: 3 | M29: 2.3 | O29: 0 | P29: Christos | Q29: 0 | R29: 557 | S29: FALSE | V29: 65 | W29: 439509.jpg | X29: 0 | Y29: FALSE | Z29: Tzolis | AA29: 0.3 | AB29: FALSE | AD29: a | AE29: 1 | AF29: 3 | AG29: 0 | AH29: 0 | AI29: 0 | AJ29: 0 | AK29: 0 | AL29: 0 | AM29: 0 | AN29: Tzolis | AP29: 83 | AQ29: 46226 | AR29: 37286 | AS29: FALSE | AT29: p439509 | AU29: 0 | AV29: 0 | AW29: 0 | AX29: 0 | AY29: 0 | AZ29: 0 | BA29: 0 | BB29: 0 | BC29: 0 | BD29: 0 | BE29: 0 | BF29: 0 | BG29: 0 | BH29: 0 | BI29: 0 | BJ29: 0 | BK29: 0 | BL29: 0 | BM29: 0 | BN29: 0 | BO29: 0 | BP29: 0 | BQ29: 0 | BR29: 0 | BS29: 0 | BT29: 0 | CC29: 554 | CD29: 243 | CE29: 554 | CF29: 243 | CG29: 554 | CH29: 243 | CI29: 554 | CJ29: 243 | CK29: 0 | CL29: 0 | CM29: 0 | CN29: 0 | CO29: 0 | CP29: 0 | CQ29: 44 | CR29: 31 | CS29: 517 | CT29: 219 | CU29: 554 | CV29: 243 | CW29: 324 | CX29: 116 | CY29: 0 | CZ29: 0 | DA29: 0
A30: TRUE | B30: TRUE | E30: 98980 | F30: 0 | G30: 0 | H30: 0 | I30: 0 | J30: 0 | K30: 0 | L30: 1 | M30: 2.6 | O30: 0 | P30: Emiliano | Q30: 0 | R30: 28 | S30: FALSE | V30: 50 | W30: 98980.jpg | X30: 3.8 | Y30: FALSE | Z30: Martínez Romero | AA30: 3.9 | AB30: FALSE | AD30: a | AE30: 2 | AF30: 7 | AG30: 120 | AH30: 0 | AI30: 0 | AJ30: 0 | AK30: 0 | AL30: 0 | AM30: 24 | AN30: Martinez | AS30: FALSE | AT30: p98980 | AU30: 2835 | AV30: 0 | AW30: 1 | AX30: 7 | AY30: 39 | AZ30: 0 | BA30: 1 | BB30: 0 | BC30: 2 | BD30: 0 | BE30: 95 | BF30: 11 | BG30: 530 | BH30: 769.8 | BI30: 23.2 | BJ30: 0 | BK30: 79.2 | BL30: 0 | BM30: 0 | BN30: 0 | BO30: 0 | BP30: 32 | BQ30: 0 | BR30: 0.08 | BS30: 0.08 | BT30: 42.92 | CC30: 34 | CD30: 10 | CE30: 319 | CF30: 4 | CG30: 479 | CH30: 48 | CI30: 175 | CJ30: 10 | CK30: 0 | CL30: 3.02 | CM30: 0 | CN30: 0 | CO30: 1.36 | CP30: 1.24 | CQ30: 220 | CR30: 7 | CS30: 198 | CT30: 45 | CU30: 69 | CV30: 7 | CW30: 88 | CX30: 14 | CY30: 1.02 | CZ30: 0.22 | DA30: 0
A31: TRUE | B31: TRUE | E31: 72147 | F31: 0 | G31: 0 | H31: 0 | I31: 0 | J31: 0 | K31: 0 | L31: 1 | M31: 2 | O31: 0 | P31: Marco | Q31: 0 | R31: 29 | S31: FALSE | V31: 45 | W31: 72147.jpg | X31: 2.3 | Y31: FALSE | Z31: Bizot | AA31: 0.1 | AB31: FALSE | AD31: a | AE31: 2 | AF31: 7 | AG31: 16 | AH31: 0 | AI31: 0 | AJ31: 0 | AK31: 0 | AL31: 0 | AM31: 3.6 | AN31: M.Bizot | AS31: FALSE | AT31: p72147 | AU31: 585 | AV31: 0 | AW31: 0 | AX31: 1 | AY31: 10 | AZ31: 0 | BA31: 0 | BB31: 0 | BC31: 2 | BD31: 0 | BE31: 19 | BF31: 0 | BG31: 75 | BH31: 139.2 | BI31: 0 | BJ31: 0 | BK31: 13.9 | BL31: 0 | BM31: 0 | BN31: 0 | BO31: 0 | BP31: 6 | BQ31: 0 | BR31: 0 | BS31: 0 | BT31: 11.02 | CC31: 283 | CD31: 21 | CE31: 436 | CF31: 35 | CG31: 419 | CH31: 26 | CI31: 323 | CJ31: 21 | CK31: 0 | CL31: 2.92 | CM31: 0 | CN31: 0 | CO31: 1.7 | CP31: 1.54 | CQ31: 371 | CR31: 20 | CS31: 70 | CT31: 22 | CU31: 253 | CV31: 25 | CW31: 411 | CX31: 48 | CY31: 0.92 | CZ31: 0.15 | DA31: 0
A32: TRUE | B32: TRUE | E32: 101188 | F32: 0 | G32: 0 | H32: 0 | I32: 0 | J32: 0 | K32: 0 | L32: 2 | M32: 1.7 | O32: 0 | P32: Lucas | Q32: 0 | R32: 30 | S32: FALSE | V32: 45 | W32: 101188.jpg | X32: 3.1 | Y32: FALSE | Z32: Digne | AA32: 1.4 | AB32: FALSE | AD32: a | AE32: 2 | AF32: 7 | AG32: 97 | AH32: 0 | AI32: 0 | AJ32: 0 | AK32: 0 | AL32: 0 | AM32: 21.6 | AN32: Digne | AS32: FALSE | AT32: p101188 | AU32: 1842 | AV32: 0 | AW32: 7 | AX32: 7 | AY32: 23 | AZ32: 0 | BA32: 0 | BB32: 0 | BC32: 3 | BD32: 0 | BE32: 0 | BF32: 5 | BG32: 381 | BH32: 400.2 | BI32: 455.5 | BJ32: 130 | BK32: 98.5 | BL32: 0 | BM32: 0 | BN32: 0 | BO32: 0 | BP32: 21 | BQ32: 0.67 | BR32: 3.28 | BS32: 3.95 | BT32: 27.79 | BU32: 4 | CC32: 153 | CD32: 63 | CE32: 60 | CF32: 11 | CG32: 206 | CH32: 56 | CI32: 134 | CJ32: 43 | CK32: 0.03 | CL32: 0 | CM32: 0.16 | CN32: 0.19 | CO32: 1.36 | CP32: 1.12 | CQ32: 376 | CR32: 77 | CS32: 75 | CT32: 51 | CU32: 154 | CV32: 61 | CW32: 168 | CX32: 63 | CY32: 1.03 | CZ32: 0.34 | DA32: 0
A33: TRUE | B33: TRUE | E33: 199798 | F33: 0 | G33: 0 | H33: 0 | I33: 0 | J33: 0 | K33: 0 | L33: 2 | M33: 1.7 | O33: 0 | P33: Ezri | Q33: 0 | R33: 31 | S33: FALSE | V33: 45 | W33: 199798.jpg | X33: 2.9 | Y33: FALSE | Z33: Konsa Ngoyo | AA33: 17.3 | AB33: FALSE | AD33: a | AE33: 2 | AF33: 7 | AG33: 100 | AH33: 0 | AI33: 0 | AJ33: 0 | AK33: 0 | AL33: 0 | AM33: 22.2 | AN33: Konsa | AS33: FALSE | AT33: p199798 | AU33: 3035 | AV33: 0 | AW33: 1 | AX33: 9 | AY33: 44 | AZ33: 0 | BA33: 0 | BB33: 0 | BC33: 0 | BD33: 1 | BE33: 0 | BF33: 3 | BG33: 497 | BH33: 601.4 | BI33: 108.3 | BJ33: 124 | BK33: 84 | BL33: 0 | BM33: 0 | BN33: 0 | BO33: 0 | BP33: 34 | BQ33: 1.27 | BR33: 0.59 | BS33: 1.86 | BT33: 48.93 | CC33: 76 | CD33: 31 | CE33: 233 | CF33: 72 | CG33: 210 | CH33: 58 | CI33: 165 | CJ33: 58 | CK33: 0.04 | CL33: 0 | CM33: 0.02 | CN33: 0.06 | CO33: 1.45 | CP33: 1.3 | CQ33: 401 | CR33: 91 | CS33: 100 | CT33: 65 | CU33: 180 | CV33: 74 | CW33: 19 | CX33: 6 | CY33: 1.01 | CZ33: 0.27 | DA33: 0
A34: TRUE | B34: TRUE | E34: 199796 | F34: 0 | G34: 0 | H34: 0 | I34: 0 | J34: 0 | K34: 0 | L34: 2 | M34: 1.7 | O34: 0 | P34: Matty | Q34: 0 | R34: 32 | S34: FALSE | V34: 45 | W34: 199796.jpg | X34: 3.3 | Y34: FALSE | Z34: Cash | AA34: 8.8 | AB34: FALSE | AD34: a | AE34: 2 | AF34: 7 | AG34: 117 | AH34: 0 | AI34: 0 | AJ34: 0 | AK34: 0 | AL34: 0 | AM34: 26 | AN34: Cash | AS34: FALSE | AT34: p199796 | AU34: 3016 | AV34: 3 | AW34: 3 | AX34: 8 | AY34: 38 | AZ34: 0 | BA34: 0 | BB34: 0 | BC34: 9 | BD34: 0 | BE34: 0 | BF34: 7 | BG34: 450 | BH34: 643 | BI34: 510.7 | BJ34: 221 | BK34: 137.5 | BL34: 0 | BM34: 0 | BN34: 0 | BO34: 0 | BP34: 34 | BQ34: 1.14 | BR34: 2.94 | BS34: 4.08 | BT34: 45.45 | BU34: 5 | CC34: 65 | CD34: 29 | CE34: 49 | CF34: 6 | CG34: 136 | CH34: 28 | CI34: 67 | CJ34: 13 | CK34: 0.03 | CL34: 0 | CM34: 0.09 | CN34: 0.12 | CO34: 1.36 | CP34: 1.13 | CQ34: 400 | CR34: 90 | CS34: 99 | CT34: 64 | CU34: 125 | CV34: 48 | CW34: 53 | CX34: 19 | CY34: 1.01 | CZ34: 0.24 | DA34: 0
A35: TRUE | B35: TRUE | E35: 149484 | F35: 0 | G35: 0 | H35: 0 | I35: 0 | J35: 0 | K35: 0 | L35: 2 | M35: 1.7 | O35: 0 | P35: Tyrone | Q35: 0 | R35: 33 | S35: FALSE | V35: 45 | W35: 149484.jpg | X35: 2.9 | Y35: FALSE | Z35: Mings | AA35: 0.2 | AB35: FALSE | AD35: a | AE35: 2 | AF35: 7 | AG35: 50 | AH35: 0 | AI35: 0 | AJ35: 0 | AK35: 0 | AL35: 0 | AM35: 11.1 | AN35: Mings | AS35: FALSE | AT35: p149484 | AU35: 1322 | AV35: 0 | AW35: 1 | AX35: 3 | AY35: 23 | AZ35: 0 | BA35: 0 | BB35: 0 | BC35: 1 | BD35: 0 | BE35: 0 | BF35: 4 | BG35: 169 | BH35: 282.6 | BI35: 80.5 | BJ35: 105 | BK35: 46.8 | BL35: 0 | BM35: 0 | BN35: 0 | BO35: 0 | BP35: 15 | BQ35: 1.3 | BR35: 0.42 | BS35: 1.72 | BT35: 23.37 | CC35: 212 | CD35: 81 | CE35: 256 | CF35: 85 | CG35: 226 | CH35: 68 | CI35: 255 | CJ35: 81 | CK35: 0.09 | CL35: 0 | CM35: 0.03 | CN35: 0.12 | CO35: 1.59 | CP35: 1.57 | CQ35: 388 | CR35: 81 | CS35: 87 | CT35: 55 | CU35: 178 | CV35: 73 | CW35: 369 | CX35: 131 | CY35: 1.02 | CZ35: 0.2 | DA35: 0
A36: TRUE | B36: TRUE | E36: 244954 | F36: 0 | G36: 0 | H36: 0 | I36: 0 | J36: 0 | K36: 0 | L36: 2 | M36: 1.7 | O36: 0 | P36: Pau | Q36: 0 | R36: 34 | S36: FALSE | V36: 45 | W36: 244954.jpg | X36: 3 | Y36: FALSE | Z36: Torres | AA36: 0.3 | AB36: FALSE | AD36: a | AE36: 2 | AF36: 7 | AG36: 64 | AH36: 0 | AI36: 0 | AJ36: 0 | AK36: 0 | AL36: 0 | AM36: 14.2 | AN36: Pau | AS36: FALSE | AT36: p244954 | AU36: 1673 | AV36: 0 | AW36: 2 | AX36: 5 | AY36: 19 | AZ36: 1 | BA36: 0 | BB36: 0 | BC36: 1 | BD36: 0 | BE36: 0 | BF36: 2 | BG36: 280 | BH36: 321.8 | BI36: 47.1 | BJ36: 79 | BK36: 45.1 | BL36: 0 | BM36: 0 | BN36: 0 | BO36: 0 | BP36: 18 | BQ36: 1.33 | BR36: 0.39 | BS36: 1.72 | BT36: 22.81 | CC36: 193 | CD36: 74 | CE36: 290 | CF36: 99 | CG36: 251 | CH36: 79 | CI36: 260 | CJ36: 85 | CK36: 0.07 | CL36: 0 | CM36: 0.02 | CN36: 0.09 | CO36: 1.23 | CP36: 1.02 | CQ36: 425 | CR36: 110 | CS36: 124 | CT36: 84 | CU36: 167 | CV36: 70 | CW36: 330 | CX36: 115 | CY36: 0.97 | CZ36: 0.27 | DA36: 0
A37: TRUE | B37: TRUE | E37: 515597 | F37: 0 | G37: 0 | H37: 0 | I37: 0 | J37: 0 | K37: 0 | L37: 3 | M37: 1.5 | O37: 0 | P37: Lamare | Q37: 0 | R37: 35 | S37: FALSE | V37: 50 | W37: 515597.jpg | X37: 1.4 | Y37: FALSE | Z37: Bogarde | AA37: 0.1 | AB37: FALSE | AD37: a | AE37: 2 | AF37: 7 | AG37: 40 | AH37: 0 | AI37: 0 | AJ37: 0 | AK37: 0 | AL37: 0 | AM37: 8 | AN37: Bogarde | AS37: FALSE | AT37: p515597 | AU37: 1042 | AV37: 0 | AW37: 0 | AX37: 2 | AY37: 17 | AZ37: 0 | BA37: 0 | BB37: 0 | BC37: 5 | BD37: 0 | BE37: 0 | BF37: 4 | BG37: 121 | BH37: 133 | BI37: 59.4 | BJ37: 14 | BK37: 20.6 | BL37: 0 | BM37: 0 | BN37: 0 | BO37: 0 | BP37: 11 | BQ37: 0 | BR37: 0.2 | BS37: 0.2 | BT37: 15.38 | CC37: 288 | CD37: 133 | CE37: 277 | CF37: 152 | CG37: 322 | CH37: 164 | CI37: 309 | CJ37: 147 | CK37: 0 | CL37: 0 | CM37: 0.02 | CN37: 0.02 | CO37: 1.33 | CP37: 1.47 | CQ37: 335 | CR37: 196 | CS37: 313 | CT37: 90 | CU37: 339 | CV37: 153 | CW37: 444 | CX37: 172 | CY37: 0.95 | CZ37: 0.17 | DA37: 0
A38: TRUE | B38: TRUE | E38: 441302 | F38: 0 | G38: 0 | H38: 0 | I38: 0 | J38: 0 | K38: 0 | L38: 2 | M38: 1.7 | O38: 0 | P38: Ian | Q38: 0 | R38: 36 | S38: FALSE | V38: 45 | W38: 441302.jpg | X38: 1.8 | Y38: FALSE | Z38: Maatsen | AA38: 0.7 | AB38: FALSE | AD38: a | AE38: 2 | AF38: 7 | AG38: 54 | AH38: 0 | AI38: 0 | AJ38: 0 | AK38: 0 | AL38: 0 | AM38: 12 | AN38: Maatsen | AS38: FALSE | AT38: p441302 | AU38: 1590 | AV38: 0 | AW38: 1 | AX38: 2 | AY38: 27 | AZ38: 0 | BA38: 0 | BB38: 0 | BC38: 2 | BD38: 0 | BE38: 0 | BF38: 1 | BG38: 242 | BH38: 336.6 | BI38: 373.4 | BJ38: 231 | BK38: 94.3 | BL38: 0 | BM38: 0 | BN38: 0 | BO38: 0 | BP38: 17 | BQ38: 1.26 | BR38: 2.39 | BS38: 3.65 | BT38: 26.64 | CC38: 180 | CD38: 71 | CE38: 90 | CF38: 21 | CG38: 130 | CH38: 25 | CI38: 142 | CJ38: 47 | CK38: 0.07 | CL38: 0 | CM38: 0.14 | CN38: 0.21 | CO38: 1.51 | CP38: 1.53 | CQ38: 430 | CR38: 115 | CS38: 129 | CT38: 89 | CU38: 299 | CV38: 111 | CW38: 239 | CX38: 86 | CY38: 0.96 | CZ38: 0.11 | DA38: 0
A39: TRUE | B39: TRUE | E39: 184667 | F39: 0 | G39: 0 | H39: 0 | I39: 0 | J39: 0 | K39: 0 | L39: 2 | M39: 1.7 | O39: 0 | P39: Victor | Q39: 0 | R39: 37 | S39: FALSE | V39: 45 | W39: 184667.jpg | X39: 1.7 | Y39: FALSE | Z39: Lindelöf | AA39: 0.2 | AB39: FALSE | AD39: a | AE39: 2 | AF39: 7 | AG39: 29 | AH39: 0 | AI39: 0 | AJ39: 0 | AK39: 0 | AL39: 0 | AM39: 6.4 | AN39: Lindelöf | AS39: FALSE | AT39: p184667 | AU39: 942 | AV39: 0 | AW39: 1 | AX39: 1 | AY39: 15 | AZ39: 0 | BA39: 0 | BB39: 0 | BC39: 0 | BD39: 0 | BE39: 0 | BF39: 0 | BG39: 124 | BH39: 167.8 | BI39: 36.6 | BJ39: 22 | BK39: 22.7 | BL39: 0 | BM39: 0 | BN39: 0 | BO39: 0 | BP39: 11 | BQ39: 0.28 | BR39: 0.1 | BS39: 0.38 | BT39: 15.93 | CC39: 262 | CD39: 99 | CE39: 302 | CF39: 103 | CG39: 307 | CH39: 106 | CI39: 307 | CJ39: 106 | CK39: 0.03 | CL39: 0 | CM39: 0.01 | CN39: 0.04 | CO39: 1.52 | CP39: 1.43 | CQ39: 397 | CR39: 87 | CS39: 96 | CT39: 61 | CU39: 311 | CV39: 114 | CW39: 380 | CX39: 134 | CY39: 1.05 | CZ39: 0.1 | DA39: 0
A40: TRUE | B40: TRUE | E40: 606798 | F40: 0 | G40: 0 | H40: 0 | I40: 0 | J40: 0 | K40: 0 | L40: 2 | M40: 1 | O40: 0 | P40: Andrés | Q40: 0 | R40: 38 | S40: FALSE | V40: 40 | W40: 606798.jpg | X40: 0.8 | Y40: FALSE | Z40: García | AA40: 1.5 | AB40: FALSE | AD40: a | AE40: 2 | AF40: 7 | AG40: 5 | AH40: 0 | AI40: 0 | AJ40: 0 | AK40: 0 | AL40: 0 | AM40: 1.2 | AN40: A.García | AS40: FALSE | AT40: p606798 | AU40: 83 | AV40: 0 | AW40: 0 | AX40: 0 | AY40: 3 | AZ40: 0 | BA40: 0 | BB40: 0 | BC40: 0 | BD40: 0 | BE40: 0 | BF40: 0 | BG40: 12 | BH40: 17.8 | BI40: 3.2 | BJ40: 2 | BK40: 2.3 | BL40: 0 | BM40: 0 | BN40: 0 | BO40: 0 | BP40: 1 | BQ40: 0 | BR40: 0.01 | BS40: 0.01 | BT40: 2.74 | CC40: 360 | CD40: 125 | CE40: 359 | CF40: 126 | CG40: 348 | CH40: 126 | CI40: 369 | CJ40: 128 | CK40: 0 | CL40: 0 | CM40: 0.01 | CN40: 0.01 | CO40: 2.97 | CP40: 3.25 | CQ40: 554 | CR40: 180 | CS40: 63 | CT40: 43 | CU40: 395 | CV40: 132 | CW40: 161 | CX40: 61 | CY40: 1.08 | CZ40: 0 | DA40: 0
...

Sheet OLD
A1: can_transact | B1: can_select | C1: chance_of_playing_next_round | D1: chance_of_playing_this_round | E1: code | F1: cost_change_event | G1: cost_change_event_fall | H1: cost_change_start | I1: cost_change_start_fall | J1: dreamteam_count | K1: element_type | L1: ep_next | M1: ep_this | N1: event_points | O1: first_name | P1: form | Q1: id | R1: in_dreamteam | S1: news | T1: news_added | U1: now_cost | V1: photo | W1: points_per_game | X1: removed | Y1: second_name | Z1: selected_by_percent | AA1: special | AB1: squad_number | AC1: status | AD1: team | AE1: team_code | AF1: total_points | AG1: transfers_in | AH1: transfers_in_event | AI1: transfers_out | AJ1: transfers_out_event | AK1: value_form | AL1: value_season | AM1: web_name | AN1: known_name | AO1: region | AP1: team_join_date | AQ1: birth_date | AR1: has_temporary_code | AS1: opta_code | AT1: minutes | AU1: goals_scored | AV1: assists | AW1: clean_sheets | AX1: goals_conceded | AY1: own_goals | AZ1: penalties_saved | BA1: penalties_missed | BB1: yellow_cards | BC1: red_cards | BD1: saves | BE1: bonus | BF1: bps | BG1: influence | BH1: creativity | BI1: threat | BJ1: ict_index | BK1: clearances_blocks_interceptions | BL1: recoveries | BM1: tackles | BN1: defensive_contribution | BO1: starts | BP1: expected_goals | BQ1: expected_assists | BR1: expected_goal_involvements | BS1: expected_goals_conceded | BT1: corners_and_indirect_freekicks_order | BU1: corners_and_indirect_freekicks_text | BV1: direct_freekicks_order | BW1: direct_freekicks_text | BX1: penalties_order | BY1: penalties_text | BZ1: scout_risks | CA1: influence_rank | CB1: influence_rank_type | CC1: creativity_rank | CD1: creativity_rank_type | CE1: threat_rank | CF1: threat_rank_type | CG1: ict_index_rank | CH1: ict_index_rank_type | CI1: expected_goals_per_90 | CJ1: saves_per_90 | CK1: expected_assists_per_90 | CL1: expected_goal_involvements_per_90 | CM1: expected_goals_conceded_per_90 | CN1: goals_conceded_per_90 | CO1: now_cost_rank | CP1: now_cost_rank_type | CQ1: form_rank | CR1: form_rank_type | CS1: points_per_game_rank | CT1: points_per_game_rank_type | CU1: selected_rank | CV1: selected_rank_type | CW1: starts_per_90 | CX1: clean_sheets_per_90 | CY1: defensive_contribution_per_90
A2: TRUE | B2: FALSE | E2: 154561 | F2: 0 | G2: 0 | H2: 7 | I2: -7 | J2: 2 | K2: 1 | L2: 8.8 | M2: 6.2 | N2: 0 | O2: David | P2: 5.2 | Q2: =DA2 -> 1 | R2: TRUE | U2: 62 | V2: 154561.jpg | W2: 4.4 | X2: FALSE | Y2: Raya Martín | Z2: 36.4 | AA2: FALSE | AC2: a | AD2: 1 | AE2: 3 | AF2: 162 | AG2: 4930540 | AH2: 0 | AI2: 3003061 | AJ2: 0 | AK2: 0.8 | AL2: 26.1 | AM2: Raya | AO2: 200 | AP2: 45477 | AQ2: 34957 | AR2: FALSE | AS2: p154561 | AT2: 3330 | AU2: 0 | AV2: 0 | AW2: 19 | AX2: 26 | AY2: 0 | AZ2: 0 | BA2: 0 | BB2: 1 | BC2: 0 | BD2: 60 | BE2: 11 | BF2: 633 | BG2: 541.6 | BH2: 33.5 | BI2: 0 | BJ2: 57.5 | BK2: 37 | BL2: 304 | BM2: 1 | BN2: 0 | BO2: 37 | BP2: 0 | BQ2: 0.07 | BR2: 0.07 | BS2: 27.56 | CA2: 108 | CB2: 17 | CC2: 391 | CD2: 3 | CE2: 833 | CF2: 97 | CG2: 279 | CH2: 17 | CI2: 0 | CJ2: 1.62 | CK2: 0 | CL2: 0 | CM2: 0.74 | CN2: 0.7 | CO2: 72 | CP2: 1 | CQ2: 20 | CR2: 1 | CS2: 36 | CT2: 3 | CU2: 5 | CV2: 1 | CW2: 1 | CX2: 0.51 | CY2: 0 | CZ2: =O2&" "&Y2 -> David Raya Martín | DA2: =VLOOKUP(CZ2,[1]FINAL!$A$1:$AP$1000,MATCH("Element No.",[1]FINAL!$A$1:$AP$1,0),0) -> 1
A3: TRUE | B3: FALSE | E3: 109745 | F3: 0 | G3: 0 | H3: -5 | I3: 5 | J3: 0 | K3: 1 | L3: 1 | M3: 1.5 | N3: 2 | O3: Kepa | P3: 0.5 | Q3: =DA3 -> 2 | R3: FALSE | U3: 40 | V3: 109745.jpg | W3: 2 | X3: FALSE | Y3: Arrizabalaga Revuelta | Z3: 0.4 | AA3: FALSE | AC3: a | AD3: 1 | AE3: 3 | AF3: 2 | AG3: 23561 | AH3: 0 | AI3: 79865 | AJ3: 0 | AK3: 0.1 | AL3: 0.5 | AM3: Arrizabalaga | AO3: 200 | AP3: 45839 | AQ3: 34610 | AR3: FALSE | AS3: p109745 | AT3: 90 | AU3: 0 | AV3: 0 | AW3: 0 | AX3: 1 | AY3: 0 | AZ3: 0 | BA3: 0 | BB3: 0 | BC3: 0 | BD3: 2 | BE3: 0 | BF3: 11 | BG3: 19.8 | BH3: 0 | BI3: 0 | BJ3: 2 | BK3: 3 | BL3: 8 | BM3: 0 | BN3: 0 | BO3: 1 | BP3: 0 | BQ3: 0 | BR3: 0 | BS3: 0.98 | CA3: 464 | CB3: 38 | CC3: 572 | CD3: 55 | CE3: 541 | CF3: 40 | CG3: 489 | CH3: 38 | CI3: 0 | CJ3: 2 | CK3: 0 | CL3: 0 | CM3: 0.98 | CN3: 1 | CO3: 679 | CP3: 44 | CQ3: 326 | CR3: 25 | CS3: 343 | CT3: 35 | CU3: 287 | CV3: 37 | CW3: 1 | CX3: 0 | CY3: 0 | CZ3: =O3&" "&Y3 -> Kepa Arrizabalaga Revuelta | DA3: =VLOOKUP(CZ3,[1]FINAL!$A$1:$AP$1000,MATCH("Element No.",[1]FINAL!$A$1:$AP$1,0),0) -> 2
A4: TRUE | B4: FALSE | C4: 0 | D4: 0 | E4: 463748 | F4: 0 | G4: 0 | H4: 0 | I4: 0 | J4: 0 | K4: 1 | L4: 0 | M4: 0 | N4: 0 | O4: Karl | P4: 0 | Q4: =DA4 -> #N/A | R4: FALSE | S4: Has joined Werder Bremen on loan for the rest of the season. | T4: 2025-08-26T13:44:02.357864Z | U4: 40 | V4: 463748.jpg | W4: 0 | X4: FALSE | Y4: Hein | Z4: 0.2 | AA4: FALSE | AC4: u | AD4: 1 | AE4: 3 | AF4: 0 | AG4: 5545 | AH4: 0 | AI4: 48759 | AJ4: 0 | AK4: 0 | AL4: 0 | AM4: Hein | AO4: 67 | AP4: 44132 | AQ4: 37359 | AR4: FALSE | AS4: p463748 | AT4: 0 | AU4: 0 | AV4: 0 | AW4: 0 | AX4: 0 | AY4: 0 | AZ4: 0 | BA4: 0 | BB4: 0 | BC4: 0 | BD4: 0 | BE4: 0 | BF4: 0 | BG4: 0 | BH4: 0 | BI4: 0 | BJ4: 0 | BK4: 0 | BL4: 0 | BM4: 0 | BN4: 0 | BO4: 0 | BP4: 0 | BQ4: 0 | BR4: 0 | BS4: 0 | CA4: 599 | CB4: 76 | CC4: 590 | CD4: 65 | CE4: 559 | CF4: 50 | CG4: 602 | CH4: 76 | CI4: 0 | CJ4: 0 | CK4: 0 | CL4: 0 | CM4: 0 | CN4: 0 | CO4: 701 | CP4: 54 | CQ4: 488 | CR4: 68 | CS4: 610 | CT4: 76 | CU4: 385 | CV4: 55 | CW4: 0 | CX4: 0 | CY4: 0 | CZ4: =O4&" "&Y4 -> Karl Hein | DA4: =VLOOKUP(CZ4,[1]FINAL!$A$1:$AP$1000,MATCH("Element No.",[1]FINAL!$A$1:$AP$1,0),0) -> #N/A
A5: TRUE | B5: FALSE | E5: 551221 | F5: 0 | G5: 0 | H5: -1 | I5: 1 | J5: 0 | K5: 1 | L5: 1 | M5: 1 | N5: 0 | O5: Tommy | P5: 0 | Q5: =DA5 -> #N/A | R5: FALSE | U5: 39 | V5: 551221.jpg | W5: 0 | X5: FALSE | Y5: Setford | Z5: 0.2 | AA5: FALSE | AC5: a | AD5: 1 | AE5: 3 | AF5: 0 | AG5: 34587 | AH5: 0 | AI5: 36016 | AJ5: 0 | AK5: 0 | AL5: 0 | AM5: Setford | AO5: 241 | AP5: 45497 | AQ5: 38789 | AR5: FALSE | AS5: p551221 | AT5: 0 | AU5: 0 | AV5: 0 | AW5: 0 | AX5: 0 | AY5: 0 | AZ5: 0 | BA5: 0 | BB5: 0 | BC5: 0 | BD5: 0 | BE5: 0 | BF5: 0 | BG5: 0 | BH5: 0 | BI5: 0 | BJ5: 0 | BK5: 0 | BL5: 0 | BM5: 0 | BN5: 0 | BO5: 0 | BP5: 0 | BQ5: 0 | BR5: 0 | BS5: 0 | CA5: 572 | CB5: 62 | CC5: 558 | CD5: 46 | CE5: 527 | CF5: 31 | CG5: 575 | CH5: 62 | CI5: 0 | CJ5: 0 | CK5: 0 | CL5: 0 | CM5: 0 | CN5: 0 | CO5: 792 | CP5: 90 | CQ5: 455 | CR5: 52 | CS5: 583 | CT5: 62 | CU5: 375 | CV5: 53 | CW5: 0 | CX5: 0 | CY5: 0 | CZ5: =O5&" "&Y5 -> Tommy Setford | DA5: =VLOOKUP(CZ5,[1]FINAL!$A$1:$AP$1000,MATCH("Element No.",[1]FINAL!$A$1:$AP$1,0),0) -> #N/A
A6: TRUE | B6: FALSE | C6: 100 | D6: 100 | E6: 226597 | F6: 0 | G6: 0 | H6: 13 | I6: -13 | J6: 5 | K6: 2 | L6: 8.8 | M6: 7 | N6: 1 | O6: Gabriel | P6: 6 | Q6: =DA6 -> 4 | R6: TRUE | T6: 2026-03-24T00:00:10.555559Z | U6: 73 | V6: 226597.jpg | W6: 6.5 | X6: FALSE | Y6: dos Santos Magalhães | Z6: 45.4 | AA6: FALSE | AC6: a | AD6: 1 | AE6: 3 | AF6: 209 | AG6: 9241680 | AH6: 0 | AI6: 6017049 | AJ6: 0 | AK6: 0.8 | AL6: 28.6 | AM6: Gabriel | AN6: Gabriel Magalhães | AO6: 30 | AP6: 44075 | AQ6: 35783 | AR6: FALSE | AS6: p226597 | AT6: 2750 | AU6: 3 | AV6: 5 | AW6: 18 | AX6: 20 | AY6: 0 | AZ6: 0 | BA6: 0 | BB6: 4 | BC6: 0 | BD6: 0 | BE6: 30 | BF6: 724 | BG6: 824 | BH6: 128.5 | BI6: 298 | BJ6: 125 | BK6: 239 | BL6: 64 | BM6: 38 | BN6: 277 | BO6: 30 | BP6: 2.94 | BQ6: 1.75 | BR6: 4.69 | BS6: 22.01 | CA6: 27 | CB6: 9 | CC6: 274 | CD6: 77 | CE6: 116 | CF6: 18 | CG6: 91 | CH6: 20 | CI6: 0.1 | CJ6: 0 | CK6: 0.06 | CL6: 0.16 | CM6: 0.72 | CN6: 0.65 | CO6: 25 | CP6: 1 | CQ6: 11 | CR6: 3 | CS6: 4 | CT6: 1 | CU6: 4 | CV6: 1 | CW6: 0.98 | CX6: 0.59 | CY6: 9.07 | CZ6: =O6&" "&Y6 -> Gabriel dos Santos Magalhães | DA6: =VLOOKUP(CZ6,[1]FINAL!$A$1:$AP$1000,MATCH("Element No.",[1]FINAL!$A$1:$AP$1,0),0) -> 4
A7: TRUE | B7: FALSE | C7: 100 | D7: 100 | E7: 462424 | F7: 0 | G7: 0 | H7: 3 | I7: -3 | J7: 2 | K7: 2 | L7: 7.5 | M7: 5.8 | N7: 0 | O7: William | P7: 4.8 | Q7: =DA7 -> 6 | R7: FALSE | T7: 2026-03-23T13:00:10.244912Z | U7: 63 | V7: 462424.jpg | W7: 4.4 | X7: FALSE | Y7: Saliba | Z7: 17.1 | AA7: FALSE | AC7: a | AD7: 1 | AE7: 3 | AF7: 137 | AG7: 2702830 | AH7: 0 | AI7: 2551293 | AJ7: 0 | AK7: 0.8 | AL7: 21.7 | AM7: Saliba | AO7: 73 | AP7: 43671 | AQ7: 36974 | AR7: FALSE | AS7: p462424 | AT7: 2614 | AU7: 1 | AV7: 0 | AW7: 15 | AX7: 20 | AY7: 0 | AZ7: 0 | BA7: 0 | BB7: 2 | BC7: 0 | BD7: 0 | BE7: 12 | BF7: 581 | BG7: 552.6 | BH7: 201 | BI7: 90 | BJ7: 84.3 | BK7: 158 | BL7: 113 | BM7: 35 | BN7: 193 | BO7: 30 | BP7: 0.88 | BQ7: 1.21 | BR7: 2.09 | BS7: 20.41 | CA7: 104 | CB7: 48 | CC7: 205 | CD7: 51 | CE7: 302 | CF7: 91 | CG7: 192 | CH7: 66 | CI7: 0.03 | CJ7: 0 | CK7: 0.04 | CL7: 0.07 | CM7: 0.7 | CN7: 0.69 | CO7: 69 | CP7: 2 | CQ7: 37 | CR7: 13 | CS7: 37 | CT7: 13 | CU7: 19 | CV7: 7 | CW7: 1.03 | CX7: 0.52 | CY7: 6.64 | CZ7: =O7&" "&Y7 -> William Saliba | DA7: =VLOOKUP(CZ7,[1]FINAL!$A$1:$AP$1000,MATCH("Element No.",[1]FINAL!$A$1:$AP$1,0),0) -> 6
A8: TRUE | B8: FALSE | C8: 100 | D8: 100 | E8: 466075 | F8: 0 | G8: 0 | H8: 1 | I8: -1 | J8: 2 | K8: 2 | L8: 4.8 | M8: 5 | N8: 1 | O8: Riccardo | P8: 4 | Q8: =DA8 -> 8 | R8: FALSE | T8: 2026-05-11T00:00:10.879576Z | U8: 56 | V8: 466075.jpg | W8: 4.2 | X8: FALSE | Y8: Calafiori | Z8: 6 | AA8: FALSE | AC8: a | AD8: 1 | AE8: 3 | AF8: 109 | AG8: 2701773 | AH8: 0 | AI8: 2532675 | AJ8: 0 | AK8: 0.7 | AL8: 19.5 | AM8: Calafiori | AO8: 106 | AP8: 45502 | AQ8: 37395 | AR8: FALSE | AS8: p466075 | AT8: 1697 | AU8: 1 | AV8: 2 | AW8: 13 | AX8: 8 | AY8: 0 | AZ8: 0 | BA8: 0 | BB8: 5 | BC8: 0 | BD8: 0 | BE8: 6 | BF8: 389 | BG8: 283 | BH8: 182.3 | BI8: 313 | BJ8: 77.9 | BK8: 70 | BL8: 74 | BM8: 32 | BN8: 102 | BO8: 22 | BP8: 3.36 | BQ8: 0.76 | BR8: 4.12 | BS8: 9.72 | CA8: 257 | CB8: 101 | CC8: 223 | CD8: 56 | CE8: 107 | CF8: 14 | CG8: 211 | CH8: 74 | CI8: 0.18 | CJ8: 0 | CK8: 0.04 | CL8: 0.22 | CM8: 0.52 | CN8: 0.42 | CO8: 131 | CP8: 13 | CQ8: 75 | CR8: 23 | CS8: 46 | CT8: 16 | CU8: 69 | CV8: 22 | CW8: 1.17 | CX8: 0.69 | CY8: 5.41 | CZ8: =O8&" "&Y8 -> Riccardo Calafiori | DA8: =VLOOKUP(CZ8,[1]FINAL!$A$1:$AP$1000,MATCH("Element No.",[1]FINAL!$A$1:$AP$1,0),0) -> 8
A9: TRUE | B9: FALSE | C9: 25 | D9: 25 | E9: 445122 | F9: 0 | G9: 0 | H9: 5 | I9: -5 | J9: 3 | K9: 2 | L9: 0.2 | M9: 0.2 | N9: 0 | O9: Jurriën | P9: 0 | Q9: =DA9 -> 5 | R9: FALSE | S9: Lack of match fitness - 25% chance of playing | T9: 2026-03-23T13:00:10.259821Z | U9: 60 | V9: 445122.jpg | W9: 5 | X9: FALSE | Y9: Timber | Z9: 15.2 | AA9: FALSE | AC9: d | AD9: 1 | AE9: 3 | AF9: 149 | AG9: 6784707 | AH9: 0 | AI9: 5670508 | AJ9: 0 | AK9: 0 | AL9: 24.8 | AM9: J.Timber | AO9: 152 | AP9: 45121 | AQ9: 37059 | AR9: FALSE | AS9: p445122 | AT9: 2452 | AU9: 3 | AV9: 6 | AW9: 13 | AX9: 20 | AY9: 0 | AZ9: 0 | BA9: 0 | BB9: 5 | BC9: 0 | BD9: 0 | BE9: 9 | BF9: 532 | BG9: 499 | BH9: 402.6 | BI9: 352 | BJ9: 125.7 | BK9: 82 | BL9: 97 | BM9: 66 | BN9: 148 | BO9: 28 | BP9: 4.71 | BQ9: 1.53 | BR9: 6.24 | BS9: 17.45 | CA9: 132 | CB9: 58 | CC9: 89 | CD9: 22 | CE9: 90 | CF9: 10 | CG9: 90 | CH9: 19 | CI9: 0.17 | CJ9: 0 | CK9: 0.06 | CL9: 0.23 | CM9: 0.64 | CN9: 0.73 | CO9: 84 | CP9: 5 | CQ9: 822 | CR9: 269 | CS9: 13 | CT9: 3 | CU9: 23 | CV9: 8 | CW9: 1.03 | CX9: 0.48 | CY9: 5.43 | CZ9: =O9&" "&Y9 -> Jurriën Timber | DA9: =VLOOKUP(CZ9,[1]FINAL!$A$1:$AP$1000,MATCH("Element No.",[1]FINAL!$A$1:$AP$1,0),0) -> 5
A10: TRUE | B10: FALSE | C10: 0 | D10: 0 | E10: 440854 | F10: 0 | G10: 0 | H10: -1 | I10: 1 | J10: 0 | K10: 2 | L10: 0 | M10: 0 | N10: 0 | O10: Jakub | P10: 0 | Q10: =DA10 -> #N/A | R10: FALSE | S10: has joined Porto on loan for the rest of the season. | T10: 2025-09-02T13:37:25.929594Z | U10: 54 | V10: 440854.jpg | W10: 0 | X10: FALSE | Y10: Kiwior | Z10: 0 | AA10: FALSE | AC10: u | AD10: 1 | AE10: 3 | AF10: 0 | AG10: 1119 | AH10: 0 | AI10: 10955 | AJ10: 0 | AK10: 0 | AL10: 0 | AM10: Kiwior | AO10: 172 | AP10: 44949 | AQ10: 36571 | AR10: FALSE | AS10: p440854 | AT10: 0 | AU10: 0 | AV10: 0 | AW10: 0 | AX10: 0 | AY10: 0 | AZ10: 0 | BA10: 0 | BB10: 0 | BC10: 0 | BD10: 0 | BE10: 0 | BF10: 0 | BG10: 0 | BH10: 0 | BI10: 0 | BJ10: 0 | BK10: 0 | BL10: 0 | BM10: 0 | BN10: 0 | BO10: 0 | BP10: 0 | BQ10: 0 | BR10: 0 | BS10: 0 | CA10: 825 | CB10: 270 | CC10: 825 | CD10: 270 | CE10: 824 | CF10: 270 | CG10: 825 | CH10: 270 | CI10: 0 | CJ10: 0 | CK10: 0 | CL10: 0 | CM10: 0 | CN10: 0 | CO10: 165 | CP10: 20 | CQ10: 804 | CR10: 268 | CS10: 825 | CT10: 270 | CU10: 596 | CV10: 212 | CW10: 0 | CX10: 0 | CY10: 0 | CZ10: =O10&" "&Y10 -> Jakub Kiwior | DA10: =VLOOKUP(CZ10,[1]FINAL!$A$1:$AP$1000,MATCH("Element No.",[1]FINAL!$A$1:$AP$1,0),0) -> #N/A
A11: TRUE | B11: FALSE | E11: 499169 | F11: 0 | G11: 0 | H11: -5 | I11: 5 | J11: 0 | K11: 2 | L11: 4.5 | M11: 4.8 | N11: 2 | O11: Myles | P11: 3.8 | Q11: =DA11 -> 7 | R11: FALSE | U11: 50 | V11: 499169.jpg | W11: 1.4 | X11: FALSE | Y11: Lewis-Skelly | Z11: 1.9 | AA11: FALSE | AC11: a | AD11: 1 | AE11: 3 | AF11: 29 | AG11: 216990 | AH11: 0 | AI11: 478401 | AJ11: 0 | AK11: 0.8 | AL11: 5.8 | AM11: Lewis-Skelly | AO11: 241 | AP11: 44899 | AQ11: 38986 | AR11: FALSE | AS11: p499169 | AT11: 697 | AU11: 0 | AV11: 0 | AW11: 2 | AX11: 8 | AY11: 0 | AZ11: 0 | BA11: 0 | BB11: 3 | BC11: 0 | BD11: 0 | BE11: 0 | BF11: 110 | BG11: 73.2 | BH11: 74.6 | BI11: 29 | BJ11: 17.6 | BK11: 17 | BL11: 30 | BM11: 8 | BN11: 25 | BO11: 5 | BP11: 0.1 | BQ11: 0.2 | BR11: 0.3 | BS11: 9.01 | CA11: 410 | CB11: 153 | CC11: 336 | CD11: 115 | CE11: 383 | CF11: 133 | CG11: 403 | CH11: 144 | CI11: 0.01 | CJ11: 0 | CK11: 0.03 | CL11: 0.04 | CM11: 1.16 | CN11: 1.03 | CO11: 268 | CP11: 41 | CQ11: 80 | CR11: 27 | CS11: 436 | CT11: 159 | CU11: 139 | CV11: 55 | CW11: 0.65 | CX11: 0.26 | CY11: 3.23 | CZ11: =O11&" "&Y11 -> Myles Lewis-Skelly | DA11: =VLOOKUP(CZ11,[1]FINAL!$A$1:$AP$1000,MATCH("Element No.",[1]FINAL!$A$1:$AP$1,0),0) -> 7
A12: TRUE | B12: FALSE | C12: 0 | D12: 0 | E12: 198869 | F12: 0 | G12: 0 | H12: -4 | I12: 4 | J12: 1 | K12: 2 | L12: 0 | M12: 0 | N12: 0 | O12: Benjamin | P12: 1.8 | Q12: =DA12 -> 10 | R12: FALSE | S12: Knee injury - Expected back 24 May | T12: 2026-05-11T00:00:10.901815Z | U12: 51 | V12: 198869.jpg | W12: 3.8 | X12: FALSE | Y12: White | Z12: 0.5 | AA12: FALSE | AC12: i | AD12: 1 | AE12: 3 | AF12: 45 | AG12: 378865 | AH12: 0 | AI12: 434751 | AJ12: 0 | AK12: 0.4 | AL12: 8.8 | AM12: White | AO12: 241 | AP12: 44407 | AQ12: 35711 | AR12: FALSE | AS12: p198869 | AT12: 699 | AU12: 0 | AV12: 1 | AW12: 5 | AX12: 6 | AY12: 0 | AZ12: 0 | BA12: 0 | BB12: 0 | BC12: 0 | BD12: 0 | BE12: 3 | BF12: 181 | BG12: 154.8 | BH12: 133.4 | BI12: 54 | BJ12: 34.3 | BK12: 38 | BL12: 28 | BM12: 15 | BN12: 53 | BO12: 9 | BP12: 0.45 | BQ12: 0.69 | BR12: 1.14 | BS12: 8.68 | CA12: 344 | CB12: 130 | CC12: 267 | CD12: 73 | CE12: 344 | CF12: 113 | CG12: 355 | CH12: 118 | CI12: 0.06 | CJ12: 0 | CK12: 0.09 | CL12: 0.15 | CM12: 1.12 | CN12: 0.77 | CO12: 226 | CP12: 33 | CQ12: 206 | CR12: 72 | CS12: 81 | CT12: 29 | CU12: 269 | CV12: 100 | CW12: 1.16 | CX12: 0.64 | CY12: 6.82 | CZ12: =O12&" "&Y12 -> Benjamin White | DA12: =VLOOKUP(CZ12,[1]FINAL!$A$1:$AP$1000,MATCH("Element No.",[1]FINAL!$A$1:$AP$1,0),0) -> 10
A13: TRUE | B13: FALSE | E13: 563324 | F13: 0 | G13: 0 | H13: -3 | I13: 3 | J13: 0 | K13: 2 | L13: 1 | M13: 1 | N13: 0 | O13: Brayden | P13: 0 | Q13: =DA13 -> #N/A | R13: FALSE | U13: 37 | V13: 563324.jpg | W13: 0 | X13: FALSE | Y13: Clarke | Z13: 0.5 | AA13: FALSE | AC13: a | AD13: 1 | AE13: 3 | AF13: 0 | AG13: 65565 | AH13: 0 | AI13: 85106 | AJ13: 0 | AK13: 0 | AL13: 0 | AM13: Clarke | AR13: FALSE | AS13: p563324 | AT13: 0 | AU13: 0 | AV13: 0 | AW13: 0 | AX13: 0 | AY13: 0 | AZ13: 0 | BA13: 0 | BB13: 0 | BC13: 0 | BD13: 0 | BE13: 0 | BF13: 0 | BG13: 0 | BH13: 0 | BI13: 0 | BJ13: 0 | BK13: 0 | BL13: 0 | BM13: 0 | BN13: 0 | BO13: 0 | BP13: 0 | BQ13: 0 | BR13: 0 | BS13: 0 | CA13: 529 | CB13: 186 | CC13: 510 | CD13: 185 | CE13: 478 | CF13: 180 | CG13: 532 | CH13: 186 | CI13: 0 | CJ13: 0 | CK13: 0 | CL13: 0 | CM13: 0 | CN13: 0 | CO13: 838 | CP13: 267 | CQ13: 404 | CR13: 141 | CS13: 540 | CT13: 186 | CU13: 279 | CV13: 105 | CW13: 0 | CX13: 0 | CY13: 0 | CZ13: =O13&" "&Y13 -> Brayden Clarke | DA13: =VLOOKUP(CZ13,[1]FINAL!$A$1:$AP$1000,MATCH("Element No.",[1]FINAL!$A$1:$AP$1,0),0) -> #N/A
A14: TRUE | B14: FALSE | C14: 0 | D14: 0 | E14: 588793 | F14: 0 | G14: 0 | H14: -1 | I14: 1 | J14: 0 | K14: 2 | L14: 0 | M14: 0 | N14: 0 | O14: Maldini | P14: 0 | Q14: =DA14 -> #N/A | R14: FALSE | S14: has joined Morecambe on loan for the rest of the season. | T14: 2025-09-22T21:14:30.857843Z | U14: 39 | V14: 588793.jpg | W14: 0 | X14: FALSE | Y14: Kacurri | Z14: 0.1 | AA14: FALSE | AC14: u | AD14: 1 | AE14: 3 | AF14: 0 | AG14: 10218 | AH14: 0 | AI14: 22844 | AJ14: 0 | AK14: 0 | AL14: 0 | AM14: Kacurri | AR14: FALSE | AS14: p588793 | AT14: 0 | AU14: 0 | AV14: 0 | AW14: 0 | AX14: 0 | AY14: 0 | AZ14: 0 | BA14: 0 | BB14: 0 | BC14: 0 | BD14: 0 | BE14: 0 | BF14: 0 | BG14: 0 | BH14: 0 | BI14: 0 | BJ14: 0 | BK14: 0 | BL14: 0 | BM14: 0 | BN14: 0 | BO14: 0 | BP14: 0 | BQ14: 0 | BR14: 0 | BS14: 0 | CA14: 577 | CB14: 210 | CC14: 563 | CD14: 209 | CE14: 532 | CF14: 205 | CG14: 580 | CH14: 210 | CI14: 0 | CJ14: 0 | CK14: 0 | CL14: 0 | CM14: 0 | CN14: 0 | CO14: 798 | CP14: 232 | CQ14: 461 | CR14: 172 | CS14: 588 | CT14: 210 | CU14: 501 | CV14: 180 | CW14: 0 | CX14: 0 | CY14: 0 | CZ14: =O14&" "&Y14 -> Maldini Kacurri | DA14: =VLOOKUP(CZ14,[1]FINAL!$A$1:$AP$1000,MATCH("Element No.",[1]FINAL!$A$1:$AP$1,0),0) -> #N/A
A15: TRUE | B15: FALSE | E15: 499167 | F15: 0 | G15: 0 | H15: -3 | I15: 3 | J15: 0 | K15: 2 | L15: 1 | M15: 1 | N15: 0 | O15: Josh | P15: 0 | Q15: =DA15 -> #N/A | R15: FALSE | U15: 37 | V15: 499167.jpg | W15: 0 | X15: FALSE | Y15: Nichols | Z15: 0.2 | AA15: FALSE | AC15: a | AD15: 1 | AE15: 3 | AF15: 0 | AG15: 34995 | AH15: 0 | AI15: 35855 | AJ15: 0 | AK15: 0 | AL15: 0 | AM15: Nichols | AO15: 241 | AP15: 45497 | AQ15: 38924 | AR15: FALSE | AS15: p499167 | AT15: 0 | AU15: 0 | AV15: 0 | AW15: 0 | AX15: 0 | AY15: 0 | AZ15: 0 | BA15: 0 | BB15: 0 | BC15: 0 | BD15: 0 | BE15: 0 | BF15: 0 | BG15: 0 | BH15: 0 | BI15: 0 | BJ15: 0 | BK15: 0 | BL15: 0 | BM15: 0 | BN15: 0 | BO15: 0 | BP15: 0 | BQ15: 0 | BR15: 0 | BS15: 0 | CA15: 528 | CB15: 185 | CC15: 508 | CD15: 183 | CE15: 476 | CF15: 178 | CG15: 531 | CH15: 185 | CI15: 0 | CJ15: 0 | CK15: 0 | CL15: 0 | CM15: 0 | CN15: 0 | CO15: 836 | CP15: 265 | CQ15: 402 | CR15: 139 | CS15: 539 | CT15: 185 | CU15: 364 | CV15: 132 | CW15: 0 | CX15: 0 | CY15: 0 | CZ15: =O15&" "&Y15 -> Josh Nichols | DA15: =VLOOKUP(CZ15,[1]FINAL!$A$1:$AP$1000,MATCH("Element No.",[1]FINAL!$A$1:$AP$1,0),0) -> #N/A
